Workbook
Name \0: #REF!
Name \0: #REF!
Name \0: #REF!
Name \0: #REF!
Name \G: #REF!
Name \G: #REF!
Name \G: #REF!
Name \G: #REF!
Name \G: #REF!
Name \G: #REF!
Name \M: #REF!
Name \M: #REF!
Name \M: #REF!
Name \M: #REF!
Name \Q: #REF!
Name \Q: #REF!
Name \Q: #REF!
Name \Q: #REF!
Name \Z: #REF!
Name \Z: #REF!
Name \Z: #REF!
Name ________ADJ81: #REF!
Name ________CEP1: #REF!
Name ________CEP2: #REF!
Name ________DAT1: #REF!
Name ________DAT10: #REF!
Name ________DAT11: #REF!
Name ________DAT12: #REF!
Name ________DAT13: #REF!
Name ________DAT14: #REF!
Name ________DAT15: #REF!
Name ________DAT16: #REF!
Name ________DAT17: #REF!
Name ________DAT18: #REF!
Name ________DAT19: #REF!
Name ________DAT2: #REF!
Name ________DAT20: #REF!
Name ________DAT21: #REF!
Name ________DAT22: #REF!
Name ________DAT23: #REF!
Name ________DAT24: #REF!
Name ________DAT25: #REF!
Name ________DAT26: #REF!
Name ________DAT27: #REF!
Name ________DAT28: #REF!
Name ________DAT29: #REF!
Name ________DAT3: #REF!
Name ________DAT30: #REF!
Name ________DAT31: #REF!
Name ________DAT32: #REF!
Name ________DAT33: #REF!
Name ________DAT34: #REF!
Name ________DAT35: #REF!
Name ________DAT36: #REF!
Name ________DAT37: #REF!
Name ________DAT38: #REF!
Name ________DAT39: #REF!
Name ________DAT4: #REF!
Name ________DAT40: #REF!
Name ________DAT41: #REF!

Sheet HC
B1: 43374 | C1: 43405 | D1: 43435 | E1: 43466 | F1: 43497 | G1: 43525 | H1: 43556 | I1: 43586 | J1: 43617 | K1: 43647 | L1: 43678 | M1: 43709 | N1: 43739 | O1: 43770 | P1: 43800 | Q1: 43831 | R1: 43862 | S1: 43891 | T1: 43922 | U1: 43952 | V1: 43983 | W1: 44043 | X1: 44074 | Y1: 44104 | Z1: 44135 | AA1: 44165 | AB1: 44196 | AC1: 44227 | AD1: 44255 | AE1: 44286 | AF1: 44316 | AG1: 44347 | AH1: Jun-2021 | AI1: Jul-2021 | AJ1: Aug-2021 | AK1: Sep-2021 | AL1: Oct-2021 | AM1: 44501 | AN1: 44531 | AO1: 44562 | AP1: 44593 | AQ1: 44621 | AR1: 44652 | AS1: 44682 | AT1: 44713 | AU1: 44743 | AV1: 44774 | AW1: 44805 | AX1: 44835 | AY1: 44866 | AZ1: 44896 | BA1: 44927 | BB1: 44958 | BC1: 44986 | BD1: 45017 | BE1: 45047 | BF1: 45078 | BG1: 45108 | BH1: 45139 | BI1: 45170 | BJ1: 45200 | BK1: 45231 | BL1: 45261 | BM1: 45292 | BN1: 45323 | BO1: 45352 | BP1: 45383 | BQ1: 45413 | BR1: 45444 | BS1: 45474 | BT1: 45505 | BU1: 45536 | BV1: 45566 | BW1: 45597 | BX1: 45627 | BY1: 45658 | BZ1: 45689 | CA1: 45717 | CB1: 45748 | CC1: 45778 | CD1: 45809 | CE1: 45839 | CF1: 45870 | CG1: 45901 | CH1: 45931 | CI1: 45962 | CJ1: 45992 | CK1: 46023 | CL1: 46054 | CM1: 46082 | CN1: 46113 | CO1: 46143 | CP1: 46174
A2: Current 3P Op | B2: 316 | C2: 271 | D2: 263 | E2: 224 | F2: 223 | G2: 221 | H2: 246 | I2: 262 | J2: 263 | K2: 265 | L2: 296 | M2: 268 | N2: 248 | O2: =N10 -> 242 | P2: =O10 -> 235 | Q2: =P10 -> 195 | R2: =Q10 -> 169 | S2: =R10 -> 148 | T2: =S10 -> 194 | U2: =T10 -> 195 | V2: =U10 -> 166 | ... CP2: =CO10 -> 349
A3: New hire | B3: 2 | D3: 0 | E3: 0 | F3: 8 | G3: 46 | H3: 31 | I3: 23 | J3: 15 | K3: 63 | L3: 0 | M3: 1 | N3: 1 | O3: 0 | P3: 0 | Q3: 0 | R3: 0 | S3: =62+17 -> 79 | T3: =11+6 -> 17 | U3: 0 | V3: 0 | W3: 0 | X3: 0 | Y3: 1 | Z3: =25 -> 25 | AA3: 76 | AB3: =13+34 -> 47 | AC3: =5+13 -> 18 | AD3: 16 | AE3: =73+32 -> 105 | AF3: =27+5 -> 32 | AG3: =49+19 -> 68 | AH3: 6 | AI3: 18 | AK3: 21 | AL3: 20 | AM3: 69 | AN3: 23 | AO3: 0 | AP3: 1 | AQ3: 58 | AR3: 1 | AS3: 18 | AT3: 19 | AU3: 0 | AV3: 29 | AW3: 0 | AX3: 0 | AY3: 0 | AZ3: 0 | BA3: 0 | BB3: 20 | BC3: 0 | BD3: 0 | BE3: 0 | BF3: 0 | BG3: 0 | BH3: 0 | BI3: 2 | BJ3: 0 | BK3: 0 | BL3: 1 | BM3: 31 | BN3: =49+5 -> 54 | BO3: 40 | BP3: 31 | BQ3: 115 | BR3: 1 | BS3: 20 | BT3: 1 | BU3: 0 | BV3: 0 | BW3: 0 | BX3: 1 | BY3: 0 | BZ3: 20 | CA3: 58 | CB3: 17 | CC3: 28 | CD3: 36 | CE3: 1 | CF3: 0 | CG3: 2 | CH3: 71 | CI3: 105 | CJ3: 30 | CK3: 28 | CL3: 0 | CM3: 147 | CN3: 96 | CO3: 97 | CP3: 106
A4: 3P Op | B4: 318 | C4: 269 | D4: 263 | E4: 224 | F4: 231 | G4: 267 | H4: 277 | I4: 285 | J4: 278 | K4: 328 | L4: 296 | M4: =M2+M3 -> 269 | N4: =N2+N3 -> 249 | O4: =O2+O3 -> 242 | P4: =P2+P3 -> 235 | Q4: =Q2+Q3 -> 195 | R4: =R2+R3 -> 169 | S4: =S2+S3 -> 227 | T4: =T2+T3 -> 211 | ... CP4: =CP2+CP3 -> 455
A5: TO | B5: 39 | C5: 45 | D5: 36 | E5: 45 | F5: 44 | G5: 45 | H5: 40 | I5: 45 | J5: 46 | K5: 49 | L5: 46 | M5: 32 | N5: 44 | O5: 34 | P5: 38 | Q5: 21 | R5: 0 | S5: 0 | T5: 0 | U5: 0 | V5: 0 | W5: 0 | X5: 0 | Y5: 0 | Z5: 0 | AA5: 0 | AB5: 0 | AC5: 0 | AD5: 0 | AE5: 0 | AF5: 0 | AG5: 0 | AH5: 0 | AI5: 0 | AJ5: 0 | AK5: 0 | AL5: 0 | AM5: 0 | AN5: 0 | AO5: 0 | AP5: 0 | AQ5: 0 | AR5: 0 | AS5: 0 | AT5: 0 | AU5: 0 | AV5: 0 | AW5: 0 | AX5: 0 | AY5: 0 | AZ5: 0 | BA5: 0 | BB5: 0 | BC5: 0 | BD5: 0 | BE5: 0 | BF5: 0 | BG5: 0 | BH5: 0 | BI5: 0 | BJ5: 0 | BK5: 0 | BL5: 0 | BM5: 0 | BN5: 0 | BO5: 0 | BP5: 0 | BQ5: 0 | BR5: 0 | BS5: 0 | BT5: 0 | BU5: 0 | BV5: 0 | BW5: 0 | BX5: 0 | BY5: 0 | BZ5: 0 | CA5: 0 | CB5: 0 | CC5: 0 | CD5: 0 | CE5: 0 | CF5: 0 | CG5: 0 | CH5: 0 | CI5: 0 | CJ5: 0 | CK5: 0 | CL5: 0 | CM5: 0 | CN5: 0 | CO5: 0 | CP5: 0
A6: SC | B6: 16 | C6: 0 | D6: 0 | E6: 0 | F6: 0 | H6: 0 | I6: 0 | K6: 0
A7: Out of payroll | B7: 0 | C7: 7 | D7: 0 | E7: 32 | F7: 0 | G7: 1 | H7: 1 | K7: 0 | AC7: 1 | AF7: 1 | AH7: 2 | AI7: 1 | AK7: 2 | AL7: 0 | AM7: 0 | AN7: 12 | AO7: 0 | AP7: 0 | AQ7: 0 | AR7: 0 | AS7: 0 | AT7: 0 | AU7: 1 | AV7: 1 | AW7: 0 | AX7: 0 | AY7: 0 | AZ7: 0 | BA7: 0 | BB7: 0 | BC7: 0 | BD7: 0 | BE7: 0 | BF7: 0 | BG7: 0 | BH7: 0 | BI7: 0 | BJ7: 0 | BK7: 0 | BL7: 0 | BM7: 0 | BN7: 1 | BO7: 0 | BP7: 0 | BQ7: 0 | BR7: 0 | BS7: 0 | BT7: 0 | BU7: 0 | BV7: 0 | BW7: 0 | BX7: 0 | BY7: 0 | BZ7: 0 | CA7: 0 | CB7: 0 | CC7: 0 | CD7: 0 | CE7: 0 | CF7: 0 | CG7: 0 | CH7: 0 | CI7: 0 | CJ7: 0 | CK7: 0 | CL7: 0 | CM7: 0 | CN7: 0 | CO7: 0 | CP7: 0
A8: Total payroll | B8: 373 | C8: 321 | D8: 299 | E8: 301 | F8: 275 | G8: 313 | H8: 318 | I8: 330 | J8: 324 | K8: 377 | L8: 342 | M8: =M4+M5 -> 301 | N8: =N4+N5 -> 293 | O8: =O4+O5 -> 276 | P8: =P4+P5 -> 273 | Q8: =Q4+Q5 -> 216 | R8: =R4+R5 -> 169 | S8: =S4+S5 -> 227 | T8: =T4+T5 -> 211 | ... AB8: =AB4+AB5 -> 239 | AC8: =AC4+AC5+AC7 -> 235 | AD8: =AD4+AD5+AD7 -> 224 | AE8: =AE4+AE5+AE7 -> 305 | AF8: =AF4+AF5+AF7 -> 287 | AG8: =AG4+AG5+AG7 -> 323 | AH8: =AH4+AH5+AH7 -> 289 | AI8: =AI4+AI5+AI7 -> 289 | AJ8: =AJ4+AJ5+AJ7 -> 273 | ... CP8: =CP4+CP5+CP7 -> 455
A9: Termination | B9: 47 | C9: 6 | D9: 39 | E9: 1 | F9: 10 | G9: 21 | H9: 15 | I9: 22 | J9: 13 | K9: 32 | L9: 28 | M9: 21 | N9: 7 | O9: 7 | P9: 40 | Q9: 26 | R9: 21 | S9: =17+16 -> 33 | T9: 16 | U9: =17+11+1 -> 29 | V9: 27 | W9: =8+1 -> 9 | X9: 6 | Y9: 7 | Z9: =2+3 -> 5 | AA9: 22 | AB9: =23 -> 23 | AC9: 26 | AD9: 24 | AE9: 51 | AF9: 31 | AG9: =30+11+1 -> 42 | AH9: 17 | AI9: 15 | AJ9: 57 | AK9: 4 | AL9: 17 | AM9: 15 | AN9: 19 | AO9: 12 | AP9: 29 | AQ9: 16 | AR9: =14+18 -> 32 | AS9: 12 | AT9: 15 | AU9: 11 | AV9: 9 | AW9: 6 | AX9: 11 | AY9: 7 | AZ9: 2 | BA9: 7 | BB9: 10 | BC9: 9 | BD9: 32 | BE9: 2 | BF9: 39 | BG9: 5 | BH9: 2 | BI9: 6 | BJ9: 62 | BK9: 49 | BL9: 1 | BM9: 2 | BN9: 10 | BO9: 8 | BP9: 9 | BQ9: 34 | BR9: 12 | BS9: 12 | BT9: 20 | BU9: 11 | BV9: 10 | BW9: 4 | BX9: 4 | BY9: 3 | BZ9: 13 | CA9: 23 | CB9: 13 | CC9: 25 | CD9: 23 | CE9: 10 | CF9: 12 | CG9: 17 | CH9: 18 | CI9: 67 | CJ9: 36 | CK9: 22 | CL9: 25 | CM9: 192 | CN9: 51 | CO9: 52 | CP9: 90
A10: T3 OP- presence | B10: 271 | C10: 263 | D10: 224 | E10: 223 | F10: 221 | G10: 246 | H10: 262 | I10: 263 | J10: 265 | K10: 296 | L10: 268 | M10: =M4-M9 -> 248 | N10: =N4-N9 -> 242 | O10: =O4-O9 -> 235 | P10: =P4-P9 -> 195 | Q10: =Q4-Q9 -> 169 | R10: =R4-R9 -> 148 | S10: =S4-S9 -> 194 | T10: =T4-T9 -> 195 | ... CP10: =CP4-CP9 -> 365
A12: Termination
A13: Voluntary | P13: 8 | Q13: 7 | R13: 21 | S13: 21 | T13: 14 | U13: =17+1 -> 18 | V13: 17 | W13: 9 | X13: 5 | Y13: 7 | Z13: 2 | AA13: 11 | AB13: 16
A14: Redundancy/not following the rule/not get performance | P14: 32 | Q14: 19 | R14: 0 | S14: 5 | T14: 0 | U14: 0 | V14: 10 | W14: 0 | X14: 0 | Y14: 0 | Z14: 0 | AA14: 0 | AB14: 4
A15: Not taking a job | P15: 0 | Q15: 0 | R15: 0 | S15: 6 | T15: 2 | U15: 0 | V15: 0 | W15: 0 | X15: 0 | Y15: 0 | Z15: 3 | AA15: 5 | AB15: 2
A16: to be regular | P16: 0 | Q16: 0 | R16: 0 | S16: 1 | T16: 0 | U16: 11 | V16: 0 | W16: 0 | X16: 1 | Y16: 0 | Z16: 0 | AA16: 6 | AB16: 1

Sheet Compare
B1: 44166 | C1: 44197 | D1: 44228 | E1: 44256 | F1: 44287 | G1: 44317 | H1: 44377 | I1: 44407 | J1: 44439 | K1: 44469 | L1: 44490 | M1: 44501 | N1: 44531 | O1: 44562 | P1: 44593 | Q1: 44621 | R1: 44652 | S1: 44682 | T1: 44713 | U1: 44743 | V1: 44774 | W1: 44805 | X1: 44835 | Y1: 44866 | Z1: 44896 | AA1: 44927 | AB1: 44958 | AC1: 44986 | AD1: 45017 | AE1: 45047 | AF1: 45078 | AG1: 45108 | AH1: 45139 | AI1: 45170 | AJ1: 45200 | AK1: 45231 | AL1: 45261 | AM1: 45292 | AN1: 45323 | AO1: 45352 | AP1: 45383 | AQ1: 45413 | AR1: 45444 | AS1: 45474 | AT1: 45505 | AU1: 45536 | AV1: 45566 | AW1: 45597 | AX1: 45627 | AY1: 45658 | AZ1: 45689 | BA1: 45717 | BB1: 45748 | BC1: 45778 | BD1: 45809 | BE1: 45839 | BF1: 45870 | BG1: 45901 | BH1: 45931 | BI1: 45962 | BJ1: 45992 | BK1: 46023 | BL1: 46054 | BM1: 46082 | BN1: 46113 | BO1: 46143 | BP1: 46174 | BQ1: May26 vs Apr26 | BR1: Unit
A2: (1) | B2: (2) | C2: (3) | D2: (4) | E2: (5) | F2: (6) | G2: (7) | H2: (8) | I2: (9) | J2: (10) | K2: (11) | L2: -12 | M2: -13 | N2: -14 | O2: -15 | P2: -16 | Q2: -17 | R2: -18 | S2: -19 | T2: -20 | U2: -21 | V2: -22 | W2: -23 | X2: -24 | Y2: -24 | Z2: -25 | AA2: -26 | AB2: -27 | AC2: -28 | AD2: -29 | AE2: -30 | AF2: -31 | AG2: -32 | AH2: (33) | AI2: (34) | AJ2: (35) | AK2: (36) | AL2: (37) | AM2: -38 | AN2: -39 | AO2: -40 | AP2: -41 | AQ2: -42 | AR2: -43 | AS2: -44 | AT2: -45 | AU2: -46 | AV2: -47 | AW2: -48 | AX2: -49 | AY2: -50 | AZ2: -51 | BA2: -52 | BB2: -53 | BC2: -54 | BD2: -55 | BE2: -56 | BF2: -57 | BG2: -58 | BH2: -59 | BI2: -60 | BJ2: -61 | BK2: -62 | BL2: -63 | BM2: -64 | BN2: -65 | BO2: -66 | BP2: -67 | BQ2: -68
A3: Số giờ làm việc được trả lương | B3: 42711.633 | C3: 43496.098 | D3: 38581.067 | E3: 48746.415 | F3: 51792.765 | G3: 55357.452 | H3: 54107.166 | I3: 49944.281 | J3: 42943.95 | K3: 44657.65 | L3: 48290.785 | M3: 54986.217 | N3: 58522.584 | O3: 55167.552 | P3: 52138.433 | Q3: 55812.551 | R3: 56310.999 | S3: 50359.032 | T3: 53953.583 | U3: 52461.45 | V3: 53346.583 | W3: 55725.817 | X3: 53955.313 | Y3: 52606.134 | Z3: 51076.8 | AA3: 47675.287 | AB3: 51045.25 | AC3: 51014.083 | AD3: 48540.166 | AE3: 44318.75 | AF3: 42273.233 | AG3: 35510.733 | AH3: 35194 | AI3: 34710.483 | AJ3: 28310.967 | AK3: 14964 | AL3: 11587.5 | AM3: 11348.297 | AN3: 18422.384 | AO3: 29485.667 | AP3: 36755.483 | AQ3: 47498.766 | AR3: 52713.234 | AS3: 49896.383 | AT3: 51872.383 | AU3: 47560.083 | AV3: 45231.25 | AW3: 44670.5 | AX3: 43931.666 | AY3: 40126.683 | AZ3: 41032.75 | BA3: 48352.734 | BB3: 51299.517 | BC3: 54490.8 | BD3: 54305.383 | BE3: 53526.017 | BF3: 52004.35 | BG3: 49211.133 | BH3: 53378.151 | BI3: 60089.1 | BJ3: 66625.15 | BK3: 63092.484 | BL3: 58167.35 | BM3: 67432.967 | BN3: 55987.95 | BO3: 64159.116 | BP3: 70177.715 | BQ3: =BP3-BO3 -> 6018.599 | BR3: hours | BW3: =BQ3/BO3 -> 0.093807387
A4: Overtime 150% (hour) | B4: 15 | C4: 11.5 | D4: 9 | E4: 27.5 | F4: 26 | G4: 16 | H4: 33 | I4: 1.5 | J4: 0 | K4: 0 | L4: 11.5 | M4: 7 | N4: 24 | O4: 16.5 | P4: 28 | Q4: 123.5 | R4: 222.5 | S4: 148 | T4: 165.5 | U4: 87.5 | V4: 297 | W4: 262 | X4: 116.5 | Y4: 166.5 | Z4: 131 | AA4: 513 | AB4: 102 | AC4: 59 | AD4: 68.5 | AE4: 312 | AF4: 50 | AG4: 0 | AH4: 37.5 | AI4: 48 | AJ4: 0 | AK4: 0 | AL4: 2.5 | AM4: 0 | AN4: 196 | AO4: 5.5 | AP4: 356 | AQ4: 654 | AR4: 37 | AS4: 25 | AT4: 21.5 | AU4: 809.5 | AV4: 12 | AW4: 18.5 | AX4: 23.5 | AY4: 8.5 | AZ4: 3.5 | BA4: 11 | BB4: 597 | BC4: 345.5 | BD4: 15.5 | BE4: 18.5 | BF4: 11 | BG4: 743.5 | BH4: 40.5 | BI4: 28 | BJ4: 214.5 | BK4: 1021.5 | BL4: 5988.75 | BM4: 13775.75 | BN4: 8870.25 | BO4: 9165.5 | BP4: 11557.75 | BQ4: =BP4-BO4 -> 2392.25 | BR4: hours
A5: Overtime 175% (hour) | B5: 10400.5 | C5: 5897.75 | D5: 3601 | E5: 14526.25 | F5: 11776.75 | G5: 14473.25 | H5: 14623 | I5: 3654 | J5: 28 | K5: 27.5 | L5: 3836.75 | M5: 15 | N5: 0 | O5: 0 | P5: 0 | Q5: 0 | R5: 0 | S5: 0 | T5: 0 | U5: 0 | V5: 0 | W5: 0 | X5: 0 | Y5: 0 | Z5: 0 | AA5: 0 | AB5: 0 | AC5: 0 | AD5: 0 | AE5: 0 | AF5: 0 | AG5: 0 | AH5: 0 | AI5: 0 | AJ5: 0 | AK5: 0 | AL5: 0 | AM5: 0 | AN5: 0 | AO5: 0 | AP5: 0 | AQ5: 0 | AR5: 0 | AS5: 0 | AT5: 0 | AU5: 0 | AV5: 0 | AW5: 0 | AX5: 0 | AY5: 0 | AZ5: 0 | BA5: 0 | BB5: 0 | BC5: 0 | BD5: 0 | BE5: 0 | BF5: 0 | BG5: 0 | BH5: 0 | BI5: 0 | BJ5: 0 | BK5: 0 | BL5: 0 | BM5: 0 | BN5: 0 | BO5: 0 | BP5: 0 | BQ5: =BP5-BO5 -> 0 | BR5: hours
A6: Overtime 200% (hour) | B6: 1339.5 | C6: 762 | D6: 1579 | E6: 1700.25 | F6: 1568 | G6: 2089.75 | H6: 2837.25 | I6: 8578 | J6: 13462.25 | K6: 18705.5 | L6: 7636.75 | M6: 11501.75 | N6: 141 | O6: 4877.25 | P6: 9473.75 | Q6: 14569.5 | R6: 9851 | S6: 10905.25 | T6: 12720 | U6: 6181.5 | V6: 10645 | W6: 13430.25 | X6: 11935.5 | Y6: 8090 | Z6: 5842.25 | AA6: 303 | AB6: 11544.25 | AC6: 7326.75 | AD6: 825.5 | AE6: 3042 | AF6: 2624.5 | AG6: 63 | AH6: 707.75 | AI6: 344 | AJ6: 36 | AK6: 40 | AL6: 60 | AM6: 2156.25 | AN6: 5015.5 | AO6: 9212.25 | AP6: 7493 | AQ6: 14013 | AR6: 20007.5 | AS6: 11363.25 | AT6: 8982.75 | AU6: 12837.25 | AV6: 2195.25 | AW6: 2894.25 | AX6: 3808.75 | AY6: 267.75 | AZ6: 6066.75 | BA6: 10411.25 | BB6: 6066.25 | BC6: 7968.75 | BD6: 9878.25 | BE6: 2268.75 | BF6: 3479.5 | BG6: 2793 | BH6: 6301.5 | BI6: 7364 | BJ6: 5114 | BK6: 4127 | BL6: 1299.75 | BM6: 5122 | BN6: 1684.25 | BO6: 1704.5 | BP6: 3387.75 | BQ6: =BP6-BO6 -> 1683.25 | BR6: hours
A7: Overtime 210% (hour) | I7: 1806 | J7: 2195.5 | K7: 4153.5 | L7: 0 | M7: 0 | N7: 10090 | O7: 0 | P7: 0 | Q7: 0 | R7: 0 | S7: 0 | T7: 0 | U7: 0 | V7: 0 | W7: 0 | X7: 0 | Y7: 0 | Z7: 0 | AA7: 0 | AB7: 0 | AC7: 0 | AD7: 0 | AE7: 0 | AF7: 0 | AG7: 0 | AH7: 0 | AI7: 0 | AJ7: 0 | AK7: 0 | AL7: 0 | AM7: 0 | AN7: 0 | AO7: 0 | AP7: 0 | AQ7: 0 | AR7: 0 | AS7: 0 | AT7: 0 | AU7: 0 | AV7: 0 | AW7: 0 | AX7: 0 | AY7: 0 | AZ7: 0 | BA7: 0 | BB7: 0 | BC7: 0 | BD7: 0 | BE7: 0 | BF7: 0 | BG7: 0 | BH7: 0 | BI7: 0 | BJ7: 0 | BK7: 0 | BL7: 0 | BM7: 0 | BN7: 0 | BO7: 0 | BP7: 0 | BQ7: =BP7-BO7 -> 0 | BR7: hours
A8: Overtime 220% (hour) | B8: 0 | C8: 0 | D8: 0 | E8: 2 | F8: 0 | G8: 0 | H8: 1.5 | I8: 0 | J8: 0 | K8: 1 | L8: 0 | M8: 0 | N8: 0 | O8: 0 | P8: 0 | Q8: 0 | R8: 0 | S8: 0 | T8: 0 | U8: 0 | V8: 0 | W8: 1 | X8: 0 | Y8: 0 | Z8: 0 | AA8: 0 | AB8: 0 | AC8: 0 | AD8: 0 | AE8: 0 | AF8: 0 | AG8: 0 | AH8: 0 | AI8: 0 | AJ8: 0 | AK8: 0 | AL8: 0 | AM8: 0 | AN8: 0 | AO8: 0 | AP8: 0 | AQ8: 0 | AR8: 0 | AS8: 0 | AT8: 0 | AU8: 0 | AV8: 0 | AW8: 0 | AX8: 0 | AY8: 0 | AZ8: 0 | BA8: 0 | BB8: 0 | BC8: 0 | BD8: 0 | BE8: 0 | BF8: 0 | BG8: 0 | BH8: 0 | BI8: 0 | BJ8: 0 | BK8: 0 | BL8: 0 | BM8: 0 | BN8: 0 | BO8: 0 | BP8: 0 | BQ8: =BP8-BO8 -> 0 | BR8: hours
A9: Overtime 290% (hour) | B9: 0 | C9: 0 | D9: 0 | E9: 0 | F9: 0 | G9: 80 | H9: 0 | I9: 0 | J9: 0 | K9: 840 | L9: 2823 | M9: 5121 | N9: 0 | O9: 1983.5 | P9: 2479.75 | Q9: 3871.25 | R9: 1464 | S9: 3722 | T9: 2776 | U9: 1512 | V9: 2160 | W9: 2888 | X9: 2728 | Y9: 1744 | Z9: 1496 | AA9: 40 | AB9: 3546.25 | AC9: 1440 | AD9: 80 | AE9: 698 | AF9: 320 | AG9: 0 | AH9: 120 | AI9: 32 | AJ9: 0 | AK9: 8 | AL9: 0 | AM9: 360 | AN9: 536 | AO9: 1656 | AP9: 1232 | AQ9: 3135.75 | AR9: 4536 | AS9: 2736 | AT9: 2176 | AU9: 2736 | AV9: 552 | AW9: 576 | AX9: 800 | AY9: 128 | AZ9: 1184 | BA9: 2704 | BB9: 1672 | BC9: 2128 | BD9: 2696 | BE9: 776 | BF9: 1029.75 | BG9: 728 | BH9: 1929.5 | BI9: 1952 | BJ9: 1544 | BK9: 1431.75 | BL9: 256 | BM9: 1624 | BN9: 400 | BO9: 360 | BP9: 616 | BQ9: =BP9-BO9 -> 256 | BR9: hours
A10: Overtime 300% (hour) | E10: 0 | F10: 0 | G10: 0 | H10: 0 | I10: 0 | J10: 0 | K10: 3163 | L10: 0 | M10: 0 | N10: 4312 | O10: 0 | P10: 0 | Q10: 0 | R10: 0 | S10: 0 | T10: 0 | U10: 0 | V10: 0 | W10: 165 | X10: 0 | Y10: 0 | Z10: 0 | AA10: 0 | AB10: 0 | AC10: 0 | AD10: 0 | AE10: 0 | AF10: 0 | AG10: 0 | AH10: 0 | AI10: 0 | AJ10: 0 | AK10: 0 | AL10: 0 | AM10: 0 | AN10: 0 | AO10: 0 | AP10: 8 | AQ10: 12 | AR10: 0 | AS10: 0 | AT10: 0 | AU10: 0 | AV10: 0 | AW10: 0 | AX10: 0 | AY10: 0 | AZ10: 0 | BA10: 0 | BB10: 0 | BC10: 0 | BD10: 0 | BE10: 0 | BF10: 0 | BG10: 0 | BH10: 0 | BI10: 0 | BJ10: 0 | BK10: 0 | BL10: 219.75 | BM10: 0 | BN10: 0 | BO10: 0 | BP10: 0 | BQ10: =BP10-BO10 -> 0 | BR10: hours
A11: Overtime 410% (hour) | C11: 0 | D11: 0 | E11: 0 | F11: 0 | G11: 0 | H11: 0 | I11: 0 | J11: 0 | K11: 20 | L11: 0 | M11: 0 | N11: 0 | O11: 0 | P11: 0 | Q11: 0 | R11: 0 | S11: 0 | T11: 0 | U11: 0 | V11: 0 | W11: 88 | X11: 0 | Y11: 0 | Z11: 0 | AA11: 0 | AB11: 0 | AC11: 0 | AD11: 0 | AE11: 0 | AF11: 0 | AG11: 0 | AH11: 0 | AI11: 0 | AJ11: 0 | AK11: 0 | AL11: 0 | AM11: 0 | AN11: 0 | AO11: 0 | AP11: 0 | AQ11: 0 | AR11: 0 | AS11: 0 | AT11: 0 | AU11: 0 | AV11: 0 | AW11: 0 | AX11: 0 | AY11: 0 | AZ11: 0 | BA11: 0 | BB11: 0 | BC11: 0 | BD11: 0 | BE11: 0 | BF11: 0 | BG11: 0 | BH11: 0 | BI11: 0 | BJ11: 0 | BK11: 0 | BL11: 120 | BM11: 0 | BN11: 0 | BO11: 0 | BP11: 0 | BQ11: =BP11-BO11 -> 0 | BR11: hours
A12: Overtime 100% (hour) | B12: 0 | C12: 0 | D12: 0 | E12: 36 | F12: 0 | G12: 0 | H12: 0 | I12: 0 | J12: 0 | K12: 0 | L12: 0 | M12: 0 | N12: 0 | O12: 0 | P12: 0 | Q12: 36 | R12: 55.75 | S12: 0 | T12: 0 | U12: 0 | V12: 0 | W12: 0 | X12: 0 | Y12: 0 | Z12: 0 | AA12: 0 | AB12: 0 | AC12: 0 | AD12: 0 | AE12: 0 | AF12: 0 | AG12: 0 | AH12: 0 | AI12: 0 | AJ12: 0 | AK12: 0 | AL12: 0 | AM12: 0 | AN12: 0 | AO12: 0 | AP12: 0 | AQ12: 0 | AR12: 0 | AS12: 28 | AT12: 4 | AU12: 0 | AV12: 0 | AW12: 0 | AX12: 0 | AY12: 0 | AZ12: 0 | BA12: 3.5 | BB12: 0 | BC12: 0 | BD12: 0 | BE12: 0 | BF12: 0 | BG12: 0 | BH12: 0 | BI12: 0 | BJ12: 0 | BK12: 0 | BL12: 0 | BM12: 0 | BN12: 0 | BO12: 0 | BP12: 0 | BQ12: =BP12-BO12 -> 0 | BR12: hours
A13: Night shift (day) | B13: 0 | C13: 0 | D13: 0 | E13: 0 | F13: 0 | G13: 0 | H13: 0 | I13: 0 | J13: 0 | K13: 0 | L13: 1119.0884 | M13: 1710.505 | N13: 1913.9076 | O13: 1516.7451 | P13: 779.9541 | Q13: 1583.9235 | R13: 1107.1927 | S13: 1424.0046 | T13: 1655.4006 | U13: 1382.6038 | V13: 1441.1435 | W13: 1481.6849 | X13: 1525.059 | Y13: 1683.6702 | Z13: 1628.5328 | AA13: 592.25 | AB13: 1357.0827 | AC13: 1652.9312 | AD13: 849.1665 | AE13: 871.0832 | AF13: 1114.4166 | AG13: 724.8733 | AH13: 905.6455 | AI13: 620.5415 | AJ13: 535.354 | AK13: 304.8748 | AL13: 161.3124 | AM13: 180.0249 | AN13: 177 | AO13: 652.9889 | AP13: 679.3762 | AQ13: 1275.2784 | AR13: 1337.5396 | AS13: 1376.8538 | AT13: 1509.0413 | AU13: 1061.8181 | AV13: 1189.9991 | AW13: 1003.7081 | AX13: 1157.7504 | AY13: 605.5371 | AZ13: 769.4581 | BA13: 1258.6248 | BB13: 1127.958 | BC13: 1329.3197 | BD13: 1342.062 | BE13: 1428.7357 | BF13: 1313.3953 | BG13: 941.458 | BH13: 1520.8714 | BI13: 1381.9161 | BJ13: 1951.618 | BK13: 1644.0825 | BL13: 972.2433 | BM13: 2023.9369 | BN13: 1330.2665 | BO13: 2197.2666 | BP13: 2190.3683 | BQ13: =BP13-BO13 -> -6.8983 | BR13: hours
A14: Day Off | B14: 171 | C14: 97 | D14: 379 | E14: 212 | F14: 197 | G14: 271 | H14: 335 | I14: 319 | J14: 275 | K14: 918 | L14: 1251 | M14: 1845 | N14: 1441 | O14: 689 | P14: 1172 | Q14: 1670 | R14: 968 | S14: 1233 | T14: 1369 | U14: 684 | V14: 1136 | W14: 1427 | X14: 1293 | Y14: 867 | Z14: 649 | AA14: 27 | AB14: 1339 | AC14: 782 | AD14: 85 | AE14: 324 | AF14: 262 | AG14: 5 | AH14: 71 | AI14: 34 | AJ14: 3 | AK14: 4 | AL14: 5 | AM14: 214 | AN14: 466 | AO14: 922 | AP14: 734 | AQ14: 1443 | AR14: 2056 | AS14: 1203 | AT14: 949 | AU14: 1310 | AV14: 229 | AW14: 290 | AX14: 386 | AY14: 33 | AZ14: 607 | BA14: 1099 | BB14: 645 | BC14: 860 | BD14: 1053 | BE14: 251 | BF14: 374 | BG14: 301 | BH14: 687 | BI14: 776 | BJ14: 555 | BK14: 462 | BL14: 160 | BM14: 568 | BN14: 175 | BO14: 189 | BP14: 363 | BQ14: =BP14-BO14 -> 174 | BR14: Days
A15: Số giờ làm thêm T.O | B15: 0 | C15: 0 | D15: 0 | E15: 0 | F15: 0 | G15: 0 | H15: 0 | I15: 0 | J15: 0 | K15: 0 | L15: 0 | M15: 0 | N15: 0 | O15: 0 | P15: 0 | Q15: 0 | R15: 0 | S15: 0 | T15: 0 | U15: 0 | V15: 0 | W15: 0 | X15: 0 | Y15: 0 | Z15: 0 | AA15: 0 | AB15: 0 | AC15: 0 | AD15: 0 | AE15: 0 | AF15: 0 | AG15: 0 | AH15: 0 | AI15: 0 | AJ15: 0 | AK15: 0 | AL15: 0 | AM15: 0 | AN15: 0 | AO15: 0 | AP15: 0 | AQ15: 0 | AR15: 0 | AS15: 0 | AT15: 0 | AU15: 0 | AV15: 0 | AW15: 0 | AX15: 0 | AY15: 0 | AZ15: 0 | BA15: 0 | BB15: 0 | BC15: 0 | BD15: 0 | BE15: 0 | BF15: 0 | BG15: 0 | BH15: 0 | BI15: 0 | BJ15: 0 | BK15: 0 | BL15: 0 | BM15: 0 | BN15: 0 | BO15: 0 | BP15: 0 | BQ15: =BP15-BO15 -> 0 | BR15: hours
A16: Lương tháng | B16: 9.9241345e+08 | C16: 1.0466725e+09 | D16: 9.2825516e+08 | E16: 1.1780599e+09 | F16: 1.2619119e+09 | G16: 1.339181e+09 | H16: 1.3166717e+09 | I16: 1.21645e+09 | J16: 1.046748e+09 | K16: 1.0844416e+09 | L16: 1.172016e+09 | M16: 1.3222308e+09 | N16: 1.4167305e+09 | O16: 1.3942185e+09 | P16: 1.3192975e+09 | Q16: 1.4042639e+09 | R16: 1.4304482e+09 | S16: 1.2759876e+09 | T16: 1.367639e+09 | U16: 1.332546e+09 | V16: 1.3480911e+09 | W16: 1.4160722e+09 | X16: 1.3652182e+09 | Y16: 1.3315176e+09 | Z16: 1.2874126e+09 | AA16: 1.2018124e+09 | AB16: 1.280137e+09 | AC16: 1.2851234e+09 | AD16: 1.2231984e+09 | AE16: 1.115305e+09 | AF16: 1.0639364e+09 | AG16: 8.9446909e+08 | AH16: 8.8539902e+08 | AI16: 8.7517543e+08 | AJ16: 7.1600524e+08 | AK16: 3.813173e+08 | AL16: 2.9723345e+08 | AM16: 2.8222722e+08 | AN16: 4.5214836e+08 | AO16: 7.3291089e+08 | AP16: 9.2500821e+08 | AQ16: 1.1698756e+09 | AR16: 1.3284214e+09 | AS16: 1.3387591e+09 | AT16: 1.3985359e+09 | AU16: 1.2820744e+09 | AV16: 1.21997e+09 | AW16: 1.2049734e+09 | AX16: 1.184798e+09 | AY16: 1.0813562e+09 | AZ16: 1.0989296e+09 | BA16: 1.2898574e+09 | BB16: 1.3812474e+09 | BC16: 1.4738159e+09 | BD16: 1.4717382e+09 | BE16: 1.4646547e+09 | BF16: 1.4178603e+09 | BG16: 1.3468218e+09 | BH16: 1.4841928e+09 | BI16: 1.6733407e+09 | BJ16: 1.8469181e+09 | BK16: 1.8791971e+09 | BL16: 1.7420459e+09 | BM16: 2.0065965e+09 | BN16: 1.6751594e+09 | BO16: 1.9071987e+09 | BP16: 2.0543648e+09 | BQ16: =BP16-BO16 -> 1.471661e+08 | BR16: vnd | BW16: =BQ16/BO16 -> 0.077163485
A17: Overtime 150% (vnd) | B17: 794836.96 | C17: 667410.71 | D17: 548437.5 | E17: 1523437.5 | F17: 1440340.9 | G17: 886363.64 | H17: 1828125 | I17: 83096.591 | J17: 0 | K17: 0 | L17: 637073.86 | M17: 387784.09 | N17: 1213505.2 | O17: 869859.05 | P17: 1542187.5 | Q17: 5650384.6 | R17: 9070078.1 | S17: 6538184.8 | T17: 8361064.3 | U17: 4639343 | V17: 12287665 | W17: 11352697 | X17: 5365220.7 | Y17: 7632053.1 | Z17: 5725092.9 | AA17: 19709135 | AB17: 4845596.6 | AC17: 2578895.3 | AD17: 2830545.2 | AE17: 12015997 | AF17: 2409375 | AG17: 0 | AH17: 1539302.9 | AI17: 1805769.2 | AJ17: 0 | AK17: 0 | AL17: 138494.32 | AM17: 0 | AN17: 7631774.5 | AO17: 260369.32 | AP17: 13608403 | AQ17: 24736757 | AR17: 1963210.2 | AS17: 1203835.2 | AT17: 1035298.3 | AU17: 32635866 | AV17: 618110.8 | AW17: 988636.36 | AX17: 1245006.6 | AY17: 409303.98 | AZ17: 168536.93 | BA17: 529687.5 | BB17: 24075918 | BC17: 13961129 | BD17: 746377.84 | BE17: 890838.07 | BF17: 564204.55 | BG17: 30239030 | BH17: 2070809.7 | BI17: 1733735.8 | BJ17: 9122333.9 | BK17: 43722058 | BL17: 2.5568323e+08 | BM17: 5.8750009e+08 | BN17: 3.7886347e+08 | BO17: 3.9053798e+08 | BP17: 4.9316481e+08 | BQ17: =BP17-BO17 -> 1.0262683e+08 | BR17: vnd
A18: Overtime 175% (vnd) | B18: 4.2329471e+08 | C18: 2.4899934e+08 | D18: 1.5217249e+08 | E18: 6.2159358e+08 | F18: 5.0288858e+08 | G18: 6.1707997e+08 | H18: 6.20316e+08 | I18: 1.5531237e+08 | J18: 1809659.1 | K18: 1777343.8 | L18: 1.6274989e+08 | M18: 640264.42 | N18: 0 | O18: 0 | P18: 0 | Q18: 0 | R18: 0 | S18: 0 | T18: 0 | U18: 0 | V18: 0 | W18: 0 | X18: 0 | Y18: 0 | Z18: 0 | AA18: 0 | AB18: 0 | AC18: 0 | AD18: 0 | AE18: 0 | AF18: 0 | AG18: 0 | AH18: 0 | AI18: 0 | AJ18: 0 | AK18: 0 | AL18: 0 | AM18: 0 | AN18: 0 | AO18: 0 | AP18: 0 | AQ18: 0 | AR18: 0 | AS18: 0 | AT18: 0 | AU18: 0 | AV18: 0 | AW18: 0 | AX18: 0 | AY18: 0 | AZ18: 0 | BA18: 0 | BB18: 0 | BC18: 0 | BD18: 0 | BE18: 0 | BF18: 0 | BG18: 0 | BH18: 0 | BI18: 0 | BJ18: 0 | BK18: 0 | BL18: 0 | BM18: 0 | BN18: 0 | BO18: 0 | BP18: 0 | BQ18: =BP18-BO18 -> 0 | BR18: vnd
A19: Overtime 200% (vnd) | B19: 63267600 | C19: 37973855 | D19: 76865505 | E19: 83646077 | F19: 77049530 | G19: 1.0295061e+08 | H19: 1.3843548e+08 | I19: 4.1689241e+08 | J19: 6.5327478e+08 | K19: 9.0702104e+08 | L19: 3.7107775e+08 | M19: 5.5726902e+08 | N19: 7785861 | O19: 2.4580608e+08 | P19: 4.7690632e+08 | Q19: 7.3378108e+08 | R19: 4.9653285e+08 | S19: 5.4869401e+08 | T19: 6.404009e+08 | U19: 3.1241941e+08 | V19: 5.3578593e+08 | W19: 6.7581634e+08 | X19: 6.005588e+08 | Y19: 4.0764541e+08 | Z19: 2.9479655e+08 | AA19: 15831469 | AB19: 5.7967955e+08 | AC19: 3.6869913e+08 | AD19: 42144362 | AE19: 1.5312751e+08 | AF19: 1.3274788e+08 | AG19: 3346875 | AH19: 35668269 | AI19: 17453846 | AJ19: 1834615.4 | AK19: 2040384.6 | AL19: 3017307.7 | AM19: 1.0830865e+08 | AN19: 2.5176779e+08 | AO19: 4.6258917e+08 | AP19: 3.7584869e+08 | AQ19: 7.0254823e+08 | AR19: 1.0029912e+09 | AS19: 6.1036769e+08 | AT19: 4.8277e+08 | AU19: 6.8852676e+08 | AV19: 1.1858283e+08 | AW19: 1.5639678e+08 | AX19: 2.0484481e+08 | AY19: 14753617 | AZ19: 3.2569914e+08 | BA19: 5.5888972e+08 | BB19: 3.2542807e+08 | BC19: 4.2747597e+08 | BD19: 5.2929245e+08 | BE19: 1.2572239e+08 | BF19: 1.8948883e+08 | BG19: 1.4998676e+08 | BH19: 3.3782048e+08 | BI19: 3.9471888e+08 | BJ19: 2.7553372e+08 | BK19: 2.3626803e+08 | BL19: 74858501 | BM19: 2.9428942e+08 | BN19: 98673274 | BO19: 98424038 | BP19: 1.9483149e+08 | BQ19: =BP19-BO19 -> 96407452 | BR19: vnd
A20: Overtime 210% (vnd) | I20: 92016346 | J20: 1.1176316e+08 | K20: 2.1137409e+08 | L20: 0 | M20: 0 | N20: 5.1241742e+08 | O20: 0 | P20: 0 | Q20: 0 | R20: 0 | S20: 0 | T20: 0 | U20: 0 | V20: 0 | W20: 0 | X20: 0 | Y20: 0 | Z20: 0 | AA20: 0 | AB20: 0 | AC20: 0 | AD20: 0 | AE20: 0 | AF20: 0 | AG20: 0 | AH20: 0 | AI20: 0 | AJ20: 0 | AK20: 0 | AL20: 0 | AM20: 0 | AN20: 0 | AO20: 0 | AP20: 0 | AQ20: 0 | AR20: 0 | AS20: 0 | AT20: 0 | AU20: 0 | AV20: 0 | AW20: 0 | AX20: 0 | AY20: 0 | AZ20: 0 | BA20: 0 | BB20: 0 | BC20: 0 | BD20: 0 | BE20: 0 | BF20: 0 | BG20: 0 | BH20: 0 | BI20: 0 | BJ20: 0 | BK20: 0 | BL20: 0 | BM20: 0 | BN20: 0 | BO20: 0 | BP20: 0 | BQ20: =BP20-BO20 -> 0
A21: Overtime 220% (vnd) | B21: 0 | C21: 0 | D21: 0 | E21: 162500 | F21: 0 | G21: 0 | H21: 121875 | I21: 0 | J21: 0 | K21: 81250 | L21: 0 | M21: 0 | N21: 0 | O21: 0 | P21: 0 | Q21: 0 | R21: 0 | S21: 0 | T21: 0 | U21: 0 | V21: 0 | W21: 81250 | X21: 0 | Y21: 0 | Z21: 0 | AA21: 0 | AB21: 0 | AC21: 0 | AD21: 0 | AE21: 0 | AF21: 0 | AG21: 0 | AH21: 0 | AI21: 0 | AJ21: 0 | AK21: 0 | AL21: 0 | AM21: 0 | AN21: 0 | AO21: 0 | AP21: 0 | AQ21: 0 | AR21: 0 | AS21: 0 | AT21: 0 | AU21: 0 | AV21: 0 | AW21: 0 | AX21: 0 | AY21: 0 | AZ21: 0 | BA21: 0 | BB21: 0 | BC21: 0 | BD21: 0 | BE21: 0 | BF21: 0 | BG21: 0 | BH21: 0 | BI21: 0 | BJ21: 0 | BK21: 0 | BL21: 0 | BM21: 0 | BN21: 0 | BO21: 0 | BP21: 0 | BQ21: =BP21-BO21 -> 0 | BR21: vnd
A22: Overtime 290% (vnd) | B22: 0 | C22: 0 | D22: 0 | E22: 0 | F22: 0 | G22: 5576923.1 | H22: 0 | I22: 0 | J22: 0 | K22: 58948077 | L22: 1.9793825e+08 | M22: 3.5917894e+08 | N22: 0 | O22: 1.446626e+08 | P22: 1.8073553e+08 | Q22: 2.8227234e+08 | R22: 1.0675737e+08 | S22: 2.7071165e+08 | T22: 2.0208762e+08 | U22: 1.100589e+08 | V22: 1.5713538e+08 | W22: 2.102539e+08 | X22: 1.9845481e+08 | Y22: 1.2709808e+08 | Z22: 1.0895077e+08 | AA22: 2900000 | AB22: 2.5775214e+08 | AC22: 1.0469558e+08 | AD22: 5827884.6 | AE22: 50733269 | AF22: 23250192 | AG22: 0 | AH22: 8778076.9 | AI22: 2320000 | AJ22: 0 | AK22: 596730.77 | AL22: 0 | AM22: 26267308 | AN22: 38993846 | AO22: 1.2031096e+08 | AP22: 89504038 | AQ22: 2.2753707e+08 | AR22: 3.2936192e+08 | AS22: 2.1273173e+08 | AT22: 1.6904769e+08 | AU22: 2.126425e+08 | AV22: 42986923 | AW22: 44860769 | AX22: 62238462 | AY22: 9971538.5 | AZ22: 91946731 | BA22: 2.0972577e+08 | BB22: 1.2976385e+08 | BC22: 1.6504904e+08 | BD22: 2.0888365e+08 | BE22: 60197308 | BF22: 79838011 | BG22: 56388269 | BH22: 1.4957203e+08 | BI22: 1.5119596e+08 | BJ22: 1.1957481e+08 | BK22: 1.1783097e+08 | BL22: 21058462 | BM22: 1.3365654e+08 | BN22: 32903846 | BO22: 29613462 | BP22: 50671923 | BQ22: =BP22-BO22 -> 21058462 | BR22: vnd
A23: Overtime 300% (vnd) | E23: 0 | F23: 0 | G23: 0 | H23: 0 | I23: 0 | J23: 0 | K23: 2.3024502e+08 | L23: 0 | M23: 0 | N23: 3.1250192e+08 | O23: 0 | P23: 0 | Q23: 0 | R23: 0 | S23: 0 | T23: 0 | U23: 0 | V23: 0 | W23: 12409615 | X23: 0 | Y23: 0 | Z23: 0 | AA23: 0 | AB23: 0 | AC23: 0 | AD23: 0 | AE23: 0 | AF23: 0 | AG23: 0 | AH23: 0 | AI23: 0 | AJ23: 0 | AK23: 0 | AL23: 0 | AM23: 0 | AN23: 0 | AO23: 0 | AP23: 600000 | AQ23: 900000 | AR23: 0 | AS23: 0 | AT23: 0 | AU23: 0 | AV23: 0 | AW23: 0 | AX23: 0 | AY23: 0 | AZ23: 0 | BA23: 0 | BB23: 0 | BC23: 0 | BD23: 0 | BE23: 0 | BF23: 0 | BG23: 0 | BH23: 0 | BI23: 0 | BJ23: 0 | BK23: 0 | BL23: 21156785 | BM23: 0 | BN23: 0 | BO23: 0 | BP23: 0 | BQ23: =BP23-BO23 -> 0 | BR23: vnd
A24: Overtime 410% (vnd) | C24: 0 | D24: 0 | E24: 0 | F24: 0 | G24: 0 | H24: 0 | I24: 0 | J24: 0 | K24: 1982980.8 | L24: 0 | M24: 0 | N24: 0 | O24: 0 | P24: 0 | Q24: 0 | R24: 0 | S24: 0 | T24: 0 | U24: 0 | V24: 0 | W24: 9114615.4 | X24: 0 | Y24: 0 | Z24: 0 | AA24: 0 | AB24: 0 | AC24: 0 | AD24: 0 | AE24: 0 | AF24: 0 | AG24: 0 | AH24: 0 | AI24: 0 | AJ24: 0 | AK24: 0 | AL24: 0 | AM24: 0 | AN24: 0 | AO24: 0 | AP24: 0 | AQ24: 0 | AR24: 0 | AS24: 0 | AT24: 0 | AU24: 0 | AV24: 0 | AW24: 0 | AX24: 0 | AY24: 0 | AZ24: 0 | BA24: 0 | BB24: 0 | BC24: 0 | BD24: 0 | BE24: 0 | BF24: 0 | BG24: 0 | BH24: 0 | BI24: 0 | BJ24: 0 | BK24: 0 | BL24: 13955769 | BM24: 0 | BN24: 0 | BO24: 0 | BP24: 0 | BQ24: =BP24-BO24 -> 0 | BR24: vnd
A25: Overtime 100% (vnd) | B25: 0 | C25: 0 | D25: 0 | E25: 769230.77 | F25: 0 | G25: 0 | H25: 0 | I25: 0 | J25: 0 | K25: 0 | L25: 0 | M25: 0 | N25: 0 | O25: 0 | P25: 0 | Q25: 905769.23 | R25: 1393750 | S25: 0 | T25: 0 | U25: 0 | V25: 0 | W25: 0 | X25: 0 | Y25: 0 | Z25: 0 | AA25: 0 | AB25: 0 | AC25: 0 | AD25: 0 | AE25: 0 | AF25: 0 | AG25: 0 | AH25: 0 | AI25: 0 | AJ25: 0 | AK25: 0 | AL25: 0 | AM25: 0 | AN25: 0 | AO25: 0 | AP25: 0 | AQ25: 0 | AR25: 0 | AS25: 749038.46 | AT25: 106730.77 | AU25: 0 | AV25: 0 | AW25: 0 | AX25: 0 | AY25: 0 | AZ25: 0 | BA25: 93389.423 | BB25: 0 | BC25: 0 | BD25: 0 | BE25: 0 | BF25: 0 | BG25: 0 | BH25: 0 | BI25: 0 | BJ25: 0 | BK25: 0 | BL25: 0 | BM25: 0 | BN25: 0 | BO25: 0 | BP25: 0 | BQ25: =BP25-BO25 -> 0 | BR25: vnd
A26: Night allowance (vnd) | B26: 0 | C26: 0 | D26: 0 | E26: 0 | F26: 0 | G26: 0 | H26: 0 | I26: 0 | J26: 0 | K26: 0 | L26: 65007600 | M26: 99297644 | N26: 1.1100332e+08 | O26: 91444129 | P26: 47036015 | Q26: 95550857 | R26: 66771915 | S26: 85718073 | T26: 99660168 | U26: 83215382 | V26: 86760656 | W26: 89202696 | X26: 91765557 | Y26: 1.0136175e+08 | Z26: 98026429 | AA26: 35672769 | AB26: 81617077 | AC26: 99414646 | AD26: 51072298 | AE26: 52419607 | AF26: 67042111 | AG26: 43584970 | AH26: 54437961 | AI26: 37344194 | AJ26: 32201280 | AK26: 18351334 | AL26: 9746820.9 | AM26: 10855148 | AN26: 10649423 | AO26: 39246834 | AP26: 40808149 | AQ26: 76589973 | AR26: 80359684 | AS26: 88547849 | AT26: 96925121 | AU26: 68224770 | AV26: 76472514 | AW26: 64498230 | AX26: 74361780 | AY26: 38922881 | AZ26: 49405298 | BA26: 80788569 | BB26: 72419522 | BC26: 85282204 | BD26: 86068778 | BE26: 91641728 | BF26: 84210507 | BG26: 60363945 | BH26: 97559781 | BI26: 88578762 | BJ26: 1.2508467e+08 | BK26: 1.1190271e+08 | BL26: 66216178 | BM26: 1.3783878e+08 | BN26: 90560450 | BO26: 1.1751892e+08 | BP26: 1.4911353e+08 | BQ26: =BP26-BO26 -> 31594616 | BR26: vnd
A27: Phụ cấp đi lại | B27: 62869537 | C27: 64218677 | D27: 58442449 | E27: 71201689 | F27: 76989898 | G27: 81294375 | H27: 77428888 | I27: 54923506 | J27: 58305288 | K27: 62330245 | L27: 69566617 | M27: 74055614 | N27: 76772468 | O27: 82434519 | P27: 76880953 | Q27: 76921126 | R27: 84855704 | S27: 78496136 | T27: 81224981 | U27: 79029031 | V27: 80080253 | W27: 84006316 | X27: 81198774 | Y27: 78563812 | Z27: 76865338 | AA27: 74308001 | AB27: 76404135 | AC27: 76276755 | AD27: 72693576 | AE27: 65319286 | AF27: 62125427 | AG27: 52201243 | AH27: 51678720 | AI27: 50928690 | AJ27: 41091840 | AK27: 21919195 | AL27: 17100000 | AM27: 20183441 | AN27: 27783372 | AO27: 43465236 | AP27: 55106453 | AQ27: 68469018 | AR27: 77856668 | AS27: 74595403 | AT27: 77070419 | AU27: 70338333 | AV27: 67082321 | AW27: 66032083 | AX27: 64946667 | AY27: 63322032 | AZ27: 63813803 | BA27: 70889766 | BB27: 76516639 | BC27: 80108830 | BD27: 80440150 | BE27: 79607898 | BF27: 76945812 | BG27: 72884927 | BH27: 77884335 | BI27: 88736445 | BJ27: 99435774 | BK27: 94934220 | BL27: 93099962 | BM27: 1.0433955e+08 | BN27: 87687572 | BO27: 99398251 | BP27: 1.1063146e+08 | BQ27: =BP27-BO27 -> 11233213 | BR27: vnd
A28: Phụ cấp nhà ở | B28: 30855023 | C28: 32206190 | D28: 29850000 | E28: 33627303 | F28: 37652079 | G28: 40251083 | H28: 39750000 | I28: 38219444 | J28: 30750000 | K28: 30686538 | L28: 35272795 | M28: 38866276 | N28: 43226024 | O28: 42450000 | P28: 39367500 | Q28: 40379232 | R28: 42550000 | S28: 39000000 | T28: 41099660 | U28: 40500000 | V28: 39286957 | W28: 42300000 | X28: 41250000 | Y28: 39600000 | Z28: 38850000 | AA28: 38400000 | AB28: 38520402 | AC28: 38100000 | AD28: 36600000 | AE28: 32700000 | AF28: 32550000 | AG28: 26250000 | AH28: 26100000 | AI28: 25500000 | AJ28: 24150000 | AK28: 8700000 | AL28: 8550000 | AM28: 8550000 | AN28: 12900000 | AO28: 20628947 | AP28: 27768572 | AQ28: 31427369 | AR28: 39750000 | AS28: 37500000 | AT28: 39282955 | AU28: 35700000 | AV28: 33750000 | AW28: 33150000 | AX28: 32650000 | AY28: 32250000 | AZ28: 32359548 | BA28: 34786988 | BB28: 38072515 | BC28: 40299466 | BD28: 40296069 | BE28: 40193478 | BF28: 38700000 | BG28: 36965199 | BH28: 38388545 | BI28: 42260857 | BJ28: 50316841 | BK28: 47890327 | BL28: 47250000 | BM28: 50678169 | BN28: 42623586 | BO28: 49761341 | BP28: 55243028 | BQ28: =BP28-BO28 -> 5481686.7 | BR28: vnd
A29: Thưởng hiệu suất | B29: 85459500 | C29: 84086000 | D29: 61354000 | E29: 83313500 | F29: 104674500 | G29: 97416500 | H29: 116703500 | I29: 81547000 | J29: 88929500 | K29: 118120500 | L29: 99000500 | M29: 119414500 | N29: 129295500 | O29: 111161000 | P29: 74724000 | Q29: 118200000 | R29: 115637811 | S29: 116137500 | T29: 124479000 | U29: 110275500 | V29: 119061500 | W29: 119817500 | X29: 121427000 | Y29: 124400000 | Z29: 110189000 | AA29: 85441500 | AB29: 83086667 | AC29: 109876095 | AD29: 104444310 | AE29: 88395238 | AF29: 99472429 | AG29: 65455048 | AH29: 74612738 | AI29: 70043119 | AJ29: 53381167 | AK29: 36256738 | AL29: 24904119 | AM29: 16295405 | AN29: 34702595 | AO29: 65326238 | AP29: 86850548 | AQ29: 102447357 | AR29: 169809929 | AS29: 118951429 | AT29: 122311048 | AU29: 117283000 | AV29: 92327000 | AW29: 97617000 | AX29: 96161000 | AY29: 76799500 | AZ29: 65235000 | BA29: 100312000 | BB29: 107023000 | BC29: 116914000 | BD29: 136441000 | BE29: 109335000 | BF29: 112595000 | BG29: 104520000 | BH29: 113927000 | BI29: 132676000 | BJ29: 136791800 | BK29: 131197500 | BL29: 111758250 | BM29: 137519176 | BN29: 109895973 | BO29: 133659034 | BP29: 169846362 | BQ29: =BP29-BO29 -> 36187328 | BR29: vnd
A30: NVXS&TB tháng | B30: 1530000 | C30: 2280000 | D30: 1770000 | E30: 1890000 | F30: 2280000 | G30: 1650000 | H30: 1920000 | I30: 3360000 | J30: 2160000 | K30: 1470000 | L30: 1710000 | M30: 2220000 | N30: 1770000 | O30: 1560000 | P30: 1980000 | Q30: 2400000 | R30: 2400000 | S30: 3090000 | T30: 2430000 | U30: 2820000 | V30: 2700000 | W30: 1770000 | X30: 2970000 | Y30: 2970000 | Z30: 2610000 | AA30: 2760000 | AB30: 1590000 | AC30: 1410000 | AD30: 2280000 | AE30: 2370000 | AF30: 1500000 | AG30: 1470000 | AH30: 2040000 | AI30: 1830000 | AJ30: 1320000 | AK30: 570000 | AL30: 660000 | AM30: 600000 | AN30: 240000 | AO30: 600000 | AP30: 1050000 | AQ30: 1050000 | AR30: 1650000 | AS30: 1830000 | AT30: 2340000 | AU30: 930000 | AV30: 1590000 | AW30: 1950000 | AX30: 1680000 | AY30: 2310000 | AZ30: 1770000 | BA30: 2010000 | BB30: 2220000 | BC30: 2550000 | BD30: 1980000 | BE30: 2010000 | BF30: 1500000 | BG30: 3120000 | BH30: 2610000 | BI30: 3180000 | BJ30: 2820000 | BK30: 2040000 | BL30: 1590000 | BM30: 1560000 | BN30: 1380000 | BO30: 2520000 | BP30: 1110000 | BQ30: =BP30-BO30 -> -1410000 | BR30: vnd
A31: Thưởng TRP | B31: 35350000 | C31: 46150000 | D31: 30450000 | E31: 38200000 | F31: 40150000 | G31: 54650000 | H31: 42600000 | I31: 28550000 | J31: 43850000 | K31: 40000000 | L31: 51900000 | M31: 43550000 | N31: 43150000 | O31: 55200000 | P31: 42400000 | Q31: 38700000 | R31: 41850000 | S31: 43300000 | T31: 44950000 | U31: 55300000 | V31: 43800000 | W31: 46150000 | X31: 56000000 | Y31: 44800000 | Z31: 42650000 | AA31: 41700000 | AB31: 42150000 | AC31: 43800000 | AD31: 52300000 | AE31: 39350000 | AF31: 39700000 | AG31: 32050000 | AH31: 32450000 | AI31: 31150000 | AJ31: 32150000 | AK31: 14250000 | AL31: 12300000 | AM31: 10500000 | AN31: 13450000 | AO31: 29750000 | AP31: 30700000 | AQ31: 36600000 | AR31: 56000000 | AS31: 43150000 | AT31: 44800000 | AU31: 52400000 | AV31: 40100000 | AW31: 39700000 | AX31: 48550000 | AY31: 33850000 | AZ31: 33500000 | BA31: 51600000 | BB31: 43800000 | BC31: 45950000 | BD31: 57850000 | BE31: 46300000 | BF31: 57000000 | BG31: 42400000 | BH31: 43550000 | BI31: 1.6416849e+08 | BJ31: 1.4406326e+08 | BK31: 1.4205081e+08 | BL31: 2.3493953e+08 | BM31: 2.9246342e+08 | BN31: 1.8913689e+08 | BO31: 2.8133024e+08 | BP31: 2.6111093e+08 | BQ31: =BP31-BO31 -> -20219318 | BR31: vnd | BW31: =BQ31/BO31 -> -0.071870403
A32: Thưởng quý | B32: 53781000 | C32: 0 | D32: 0 | E32: 67781000 | F32: 0 | G32: 0 | H32: 75767143 | I32: 0 | J32: 0 | K32: 55141096 | L32: 0 | M32: 0 | N32: 94266667 | O32: 0 | P32: 0 | Q32: 95700000 | R32: 0 | S32: 0 | T32: 96009235 | U32: 0 | V32: 0 | W32: 104024460 | X32: 0 | Y32: 0 | Z32: 105657000 | AA32: 0 | AB32: 0 | AC32: 94703241 | AD32: 0 | AE32: 0 | AF32: 100694000 | AG32: 0 | AH32: 0 | AI32: 81215056 | AJ32: 0 | AK32: 0 | AL32: 26361112 | AM32: 0 | AN32: 0 | AO32: 31499000 | AP32: 0 | AQ32: 0 | AR32: 77682407 | AS32: 0 | AT32: 0 | AU32: 96018536 | AV32: 0 | AW32: 0 | AX32: 100631491 | AY32: 0 | AZ32: 0 | BA32: 88714839 | BB32: 0 | BC32: 0 | BD32: 98424043 | BE32: 0 | BF32: 0 | BG32: 106713547 | BH32: 0 | BI32: 0 | BJ32: 113453489 | BK32: 0 | BL32: 0 | BM32: 105268176 | BN32: 0 | BO32: 0 | BP32: 83317235 | BQ32: =BP32-BO32 -> 83317235 | BR32: vnd
A33: Lương tháng 13 | B33: 0 | C33: 0 | D33: 0 | E33: 0 | F33: 0 | G33: 0 | H33: 0 | I33: 0 | J33: 0 | K33: 0 | L33: 0 | M33: 0 | N33: 0 | O33: 0 | P33: 0 | Q33: 0 | R33: 0 | S33: 0 | T33: 0 | U33: 0 | V33: 0 | W33: 0 | X33: 0 | Y33: 0 | Z33: 0 | AA33: 0 | AB33: 0 | AC33: 0 | AD33: 0 | AE33: 0 | AF33: 0 | AG33: 0 | AH33: 0 | AI33: 0 | AJ33: 0 | AK33: 0 | AL33: 0 | AM33: 0 | AN33: 0 | AO33: 0 | AP33: 0 | AQ33: 0 | AR33: 0 | AS33: 0 | AT33: 0 | AU33: 0 | AV33: 0 | AW33: 0 | AX33: 0 | AY33: 0 | AZ33: 0 | BA33: 0 | BB33: 0 | BC33: 0 | BD33: 0 | BE33: 0 | BF33: 0 | BG33: 0 | BH33: 0 | BI33: 0 | BJ33: 0 | BK33: 0 | BL33: 0 | BM33: 0 | BN33: 0 | BO33: 0 | BP33: 0 | BQ33: =BP33-BO33 -> 0 | BR33: vnd
A34: Thưởng ca ngày (12h) | B34: 0 | C34: 0 | D34: 0 | E34: 0 | F34: 0 | G34: 0 | H34: 0 | I34: 0 | J34: 0 | K34: 0 | L34: 44069952 | M34: 55082933 | N34: 59175000 | O34: 58825962 | P34: 46525481 | Q34: 74406298 | R34: 65310144 | S34: 60255337 | T34: 68671707 | U34: 66533870 | V34: 73185168 | W34: 63384736 | X34: 64591010 | Y34: 65502115 | Z34: 61589159 | AA34: 29730937 | AB34: 61625721 | AC34: 68102644 | AD34: 48263702 | AE34: 51259375 | AF34: 57311298 | AG34: 42212740 | AH34: 42556250 | AI34: 44369216 | AJ34: 35120428 | AK34: 23275481 | AL34: 15439663 | AM34: 16325721 | AN34: 21444231 | AO34: 40386779 | AP34: 45032933 | AQ34: 64345913 | AR34: 64898077 | AS34: 75766346 | AT34: 73892788 | AU34: 56794231 | AV34: 70102644 | AW34: 65389904 | AX34: 57916346 | AY34: 45166346 | AZ34: 54077404 | BA34: 68530048 | BB34: 64217308 | BC34: 76263462 | BD34: 75382452 | BE34: 81184856 | BF34: 74279808 | BG34: 67132933 | BH34: 73850481 | BI34: 79720433 | BJ34: 92450481 | BK34: 82387740 | BL34: 0 | BM34: 0 | BN34: 0 | BO34: 0 | BP34: 0 | BQ34: =BP34-BO34 -> 0 | BR34: vnd
A35: Thưởng ca đêm (12h) | B35: 0 | C35: 0 | D35: 0 | E35: 0 | F35: 0 | G35: 0 | H35: 0 | I35: 0 | J35: 0 | K35: 0 | L35: 97511400 | M35: 1.4894647e+08 | N35: 1.6650498e+08 | O35: 1.3716619e+08 | P35: 70554023 | Q35: 1.4332628e+08 | R35: 1.0015787e+08 | S35: 1.2857711e+08 | T35: 1.4949025e+08 | U35: 1.2482307e+08 | V35: 1.3014098e+08 | W35: 1.3380404e+08 | X35: 1.3764833e+08 | Y35: 1.5204263e+08 | Z35: 1.4703964e+08 | AA35: 53509154 | AB35: 1.2242562e+08 | AC35: 1.4912197e+08 | AD35: 76608447 | AE35: 78629411 | AF35: 1.0056317e+08 | AG35: 65377455 | AH35: 81656941 | AI35: 56016291 | AJ35: 48301921 | AK35: 27527001 | AL35: 14620231 | AM35: 16282722 | AN35: 15974135 | AO35: 58870251 | AP35: 61212223 | AQ35: 1.1488496e+08 | AR35: 1.2053953e+08 | AS35: 1.3282177e+08 | AT35: 1.4538768e+08 | AU35: 1.0233715e+08 | AV35: 1.1470877e+08 | AW35: 96530037 | AX35: 1.1154267e+08 | AY35: 58384321 | AZ35: 74107946 | BA35: 1.2118285e+08 | BB35: 1.0862928e+08 | BC35: 1.2792331e+08 | BD35: 1.2910317e+08 | BE35: 1.3746259e+08 | BF35: 1.2631576e+08 | BG35: 90545918 | BH35: 1.4633967e+08 | BI35: 1.3286814e+08 | BJ35: 1.8762701e+08 | BK35: 1.6785406e+08 | BL35: 71734193 | BM35: 1.4932535e+08 | BN35: 98107154 | BO35: 1.2731216e+08 | BP35: 1.6153966e+08 | BQ35: =BP35-BO35 -> 34227500 | BR35: vnd
A36: Ca 2 | B36: 800.7809 | C36: 1257.3311 | D36: 544.3124 | E36: 810.3977 | F36: 814.8665 | G36: 772.2622 | H36: 681.875 | I36: 272.1163 | J36: 7 | K36: 0 | L36: 0 | M36: 0 | N36: 0 | O36: 0 | P36: 0 | Q36: 0 | R36: 0 | S36: 0 | T36: 0 | U36: 0 | V36: 0 | W36: 10 | X36: 0 | Y36: 0 | Z36: 0 | AA36: 162.0248 | AB36: 0 | AC36: 0 | AD36: 320.9687 | AE36: 191.5 | AF36: 0 | AG36: 0 | AH36: 153 | AI36: 0 | AJ36: 0 | AK36: 0 | AL36: 0 | AM36: 0 | AN36: 0 | AO36: 0 | AP36: 0 | AQ36: 0 | AR36: 0 | AS36: 0 | AT36: 0 | AU36: 0 | AV36: 0 | AW36: 0 | AX36: 35 | AY36: 26 | AZ36: 0 | BA36: 0 | BB36: 23.9978 | BC36: 0 | BD36: 0 | BE36: 0 | BF36: 0 | BG36: 0 | BH36: 0 | BI36: 0 | BJ36: 0 | BK36: 1 | BL36: 2 | BM36: 0 | BN36: 7.8896 | BO36: 0 | BP36: 0 | BQ36: =BP36-BO36 -> 0 | BR36: Days
A37: P/c ca 2 | B37: 14827494 | C37: 24029310 | D37: 10383003 | E37: 15764589 | F37: 15826183 | G37: 14987134 | H37: 13210481 | I37: 5274159.6 | J37: 135000 | K37: 0 | L37: 0 | M37: 0 | N37: 0 | O37: 0 | P37: 0 | Q37: 0 | R37: 0 | S37: 0 | T37: 0 | U37: 0 | V37: 0 | W37: 200384.62 | X37: 0 | Y37: 0 | Z37: 0 | AA37: 3254745.2 | AB37: 0 | AC37: 0 | AD37: 6437643.2 | AE37: 3840000 | AF37: 0 | AG37: 0 | AH37: 3068076.9 | AI37: 0 | AJ37: 0 | AK37: 0 | AL37: 0 | AM37: 0 | AN37: 0 | AO37: 0 | AP37: 0 | AQ37: 0 | AR37: 0 | AS37: 0 | AT37: 0 | AU37: 0 | AV37: 0 | AW37: 0 | AX37: 748653.85 | AY37: 558269.23 | AZ37: 0 | BA37: 0 | BB37: 514376.11 | BC37: 0 | BD37: 0 | BE37: 0 | BF37: 0 | BG37: 0 | BH37: 0 | BI37: 0 | BJ37: 0 | BK37: 22692.308 | BL37: 45384.615 | BM37: 0 | BN37: 179033.23 | BO37: 0 | BP37: 0 | BQ37: =BP37-BO37 -> 0 | BR37: vnd
A38: Ca 3 | B38: 1306.5374 | C38: 832 | D38: 493.804 | E38: 1812.9269 | F38: 1483.9936 | G38: 1964.1789 | H38: 2253.4916 | I38: 1009.0937 | J38: 1758.9687 | K38: 1435 | L38: 460.8352 | M38: 0 | N38: 0 | O38: 0 | P38: 7 | Q38: 0 | R38: 81 | S38: 0 | T38: 0 | U38: 0 | V38: 5 | W38: 36 | X38: 0 | Y38: 0 | Z38: 0 | AA38: 57 | AB38: 0 | AC38: 0 | AD38: 53 | AE38: 111.9375 | AF38: 0 | AG38: 0 | AH38: 77 | AI38: 0 | AJ38: 0 | AK38: 0 | AL38: 0 | AM38: 0 | AN38: 0 | AO38: 0 | AP38: 0 | AQ38: 49 | AR38: 0 | AS38: 0 | AT38: 0 | AU38: 60 | AV38: 0 | AW38: 0 | AX38: 0 | AY38: 31 | AZ38: 0 | BA38: 0 | BB38: 63 | BC38: 32 | BD38: 0 | BE38: 0 | BF38: 0 | BG38: 67 | BH38: 0 | BI38: 0 | BJ38: 5 | BK38: 199.1728 | BL38: 220 | BM38: 458 | BN38: 532.9374 | BO38: 471 | BP38: 492.7478 | BQ38: =BP38-BO38 -> 21.7478 | BR38: Days
A39: P/c ca 3 | B39: 1.2114768e+08 | C39: 79476923 | D39: 47304439 | E39: 1.7641797e+08 | F39: 1.4429256e+08 | G39: 1.9056161e+08 | H39: 2.1838567e+08 | I39: 97584971 | J39: 1.7068834e+08 | K39: 1.3895865e+08 | L39: 44650500 | M39: 0 | N39: 0 | O39: 0 | P39: 702884.62 | Q39: 0 | R39: 8131730.8 | S39: 0 | T39: 0 | U39: 0 | V39: 505769.23 | W39: 3605769.2 | X39: 0 | Y39: 0 | Z39: 0 | AA39: 5719230.8 | AB39: 0 | AC39: 0 | AD39: 5311538.5 | AE39: 11201442 | AF39: 0 | AG39: 0 | AH39: 7719230.8 | AI39: 0 | AJ39: 0 | AK39: 0 | AL39: 0 | AM39: 0 | AN39: 0 | AO39: 0 | AP39: 0 | AQ39: 4915384.6 | AR39: 0 | AS39: 0 | AT39: 0 | AU39: 6422115.4 | AV39: 0 | AW39: 0 | AX39: 0 | AY39: 3325961.5 | AZ39: 0 | BA39: 0 | BB39: 6732692.3 | BC39: 3417307.7 | BD39: 0 | BE39: 0 | BF39: 0 | BG39: 7167307.7 | BH39: 0 | BI39: 0 | BJ39: 533653.85 | BK39: 22566000 | BL39: 24971154 | BM39: 51988462 | BN39: 60467897 | BO39: 53440385 | BP39: 55907923 | BQ39: =BP39-BO39 -> 2467538.8 | BR39: vnd
A40: Ca Lỡ | I40: 0 | J40: 29.25 | K40: 0 | L40: 0 | M40: 0 | N40: 0 | O40: 0 | P40: 0 | Q40: 0 | R40: 0 | S40: 0 | T40: 0 | U40: 0 | V40: 0 | W40: 0 | X40: 0 | Y40: 0 | Z40: 0 | AA40: 0 | AB40: 0 | AC40: 0 | AD40: 0 | AE40: 0 | AF40: 0 | AG40: 0 | AH40: 0 | AI40: 0 | AJ40: 0 | AK40: 0 | AL40: 0 | AM40: 0 | AN40: 0 | AO40: 0 | AP40: 0 | AQ40: 0 | AR40: 0 | AS40: 0 | AT40: 0 | AU40: 0 | AV40: 0 | AW40: 0 | AX40: 0 | AY40: 0 | AZ40: 0 | BA40: 0 | BB40: 0 | BC40: 0 | BD40: 0 | BE40: 0 | BF40: 0 | BG40: 0 | BH40: 0 | BI40: 0 | BJ40: 0 | BK40: 0 | BL40: 0 | BM40: 0 | BN40: 0 | BO40: 0 | BP40: 0 | BQ40: =BP40-BO40 -> 0
...

Sheet Oct21 vs.Sep21
A1: Month | B1: Count | C1: DepartmentCode | D1: EmployeeID | E1: Global code | F1: FullName | I1: CostCenter | J1: Working hour | K1: Lương cơ bản | L1: Số ngày công chuẩn | M1: Số giờ công chuẩn | N1: Số ngày làm việc được trả lương | O1: Số giờ làm việc được trả lương | P1: Overtime 150% (hour) | Q1: Overtime 175% (hour) | R1: Overtime 200% (hour) | S1: Overtime 210% (hour) | U1: Overtime 270% (hour) | W1: Overtime 390% (hour) | X1: Overtime 100% (hour) | Y1: Night shift (day) | Z1: Day Off | AA1: Số giờ làm thêm T.O | AB1: Lương tháng 12-2020 | AC1: Overtime 150% (vnd) | AD1: Overtime 175% (vnd) | AE1: Overtime 200% (vnd) | AF1: Overtime 210% (vnd) | AH1: Overtime 270% (vnd) | AJ1: Overtime 390% (hour) | AK1: Overtime 100% (vnd) | AL1: Night allowance (vnd) | AM1: Phụ cấp đi lại | AN1: Phụ cấp nhà ở | AO1: Thưởng hiệu suất | AP1: NVXS&TB tháng | AQ1: Thưởng TRP | AR1: Thưởng quý 4-2020 | AS1: Lương tháng 13 | AT1: Thưởng ca ngày (12h) | AU1: Thưởng ca đêm (12h) | AV1: Ca 2 | AW1: P/c ca 2 | AX1: Ca 3 | AY1: P/c ca 3 | BD1: Sat/Sun transportation | BG1: P/c bữa ăn ca chính 10-2020 | BH1: P/c bữa ăn OT 10-2020 | BI1: Số ngày nghỉ không việc | BJ1: Lương nghỉ không việc | BK1: Lương làm thêm TO | BL1: Phụ cấp khác | BM1: Phí dịch vụ thời gian TO | BN1: ESD | BO1: ESD OT | BP1: Phí dịch vụ | BQ1: Phí dịch vụ OT | BR1: Bù-trừ ESD | BS1: Bù-trừ (11-2020) | BT1: BHXH, BHYT, BHTN&BNN (NSDLĐ) | BU1: BHXH, BHYT, BHTN&BNN (NLĐ) | BV1: Ma chay cưới hỏi (giờ) | BW1: Ma chay cưới hỏi | BX1: Phép năm nhân viên đã sử dụng (giờ) | BY1: Phép năm nhân viên đã sử dụng | BZ1: Phép năm còn lại (giờ) | CA1: Phép năm còn lại | CB1: Tổng chi phí phải trả cho NCC | CC1: Nhân viên thực lãnh | CD1: Notes | CE1: Agency
K2: 2755200000 | L2: 0 | M2: 94224 | N2: 0 | O2: 70177.715 | P2: 11557.75 | Q2: 0 | R2: 3387.75 | S2: 0 | T2: 0 | U2: 616 | V2: 0 | W2: 0 | X2: 0 | Y2: 2190.3683 | Z2: 363 | AA2: 0 | AB2: 2.0543648e+09 | AC2: 4.9316481e+08 | AD2: 0 | AE2: 1.9483149e+08 | AF2: 0 | AG2: 0 | AH2: 50671923 | AI2: 0 | AJ2: 0 | AK2: 0 | AL2: 1.4911353e+08 | AM2: 1.1063146e+08 | AN2: 55243028 | AO2: 169846362 | AP2: 1110000 | AQ2: 2.6111093e+08 | AR2: 83317235 | AS2: 0 | AT2: 0 | AU2: 1.6153966e+08 | AV2: 0 | AW2: 0 | AX2: 492.7478 | AY2: 55907923 | AZ2: 0 | BA2: 0 | BB2: 5743 | BC2: 1.629024e+08 | BD2: 10980000 | BE2: 12002864 | BF2: 41450000 | BG2: 48878000 | BH2: 156212000 | BI2: 0 | BJ2: 0 | BK2: 0 | BL2: 53756141 | BM2: 0 | BN2: 0 | BO2: 0 | BP2: 1.3401662e+08 | BQ2: 29568717 | BR2: 0 | BS2: 1616827 | BT2: 477084500 | BU2: 232348500 | BV2: 20 | BW2: 567307.69 | BX2: 944.25 | BY2: 28527644 | BZ2: 499.83 | CA2: 16208795 | CB2: 5.1046923e+09 | CC2: 4.1125179e+09 | CD2: 0 | CE2: 0 | CH2: 0 | CI2: 34994000 | CJ2: 84162000 | CK2: 0 | CL2: 2.4774734e+08

Sheet June
D1: Còn làm việc | F1: Mới gia nhập | H1: Nghỉ việc | J1: Tổng nhân viên thời vụ
A2: Agency | B2: DepartmentCode | C2: CostCenter | D2: Tổng chi phí phải trả cho NCC | E2: Số lượng NV | F2: Tổng chi phí phải trả cho NCC | G2: Số lượng NV | H2: Tổng chi phí phải trả cho NCC | I2: Số lượng NV | J2: Tổng chi phí phải trả cho NCC | K2: Số lượng NV
A3: MEKONG SUBLABOR | B3: LG | C3: VN1006 | D3: =SUMIFS('06-2026'!$CB$7:$CB$463,'06-2026'!$C$7:$C$463,$B3,'06-2026'!$A$7:$A$463,"Out",'06-2026'!$I$7:$I$463,$C3,'06-2026'!$CE$7:$CE$463,$A3) -> 0 | E3: =COUNTIFS('06-2026'!$C$7:$C$463,$B3,'06-2026'!$A$7:$A$463,"Out",'06-2026'!$I$7:$I$463,$C3,'06-2026'!$CE$7:$CE$463,$A3) -> 0 | F3: =SUMIFS('06-2026'!$CB$7:$CB$463,'06-2026'!$C$7:$C$463,$B3,'06-2026'!$A$7:$A$463,"Out-New",'06-2026'!$I$7:$I$463,$C3,'06-2026'!$CE$7:$CE$463,$A3) -> 0 | G3: =COUNTIFS('06-2026'!$C$7:$C$463,$B3,'06-2026'!$A$7:$A$463,"Out-New",'06-2026'!$I$7:$I$463,$C3,'06-2026'!$CE$7:$CE$463,$A3) -> 0 | H3: =SUMIFS('06-2026'!$CB$7:$CB$463,'06-2026'!$C$7:$C$463,$B3,'06-2026'!$A$7:$A$463,"Termination",'06-2026'!$I$7:$I$463,$C3,'06-2026'!$CE$7:$CE$463,$A3) -> 16202924 | I3: =COUNTIFS('06-2026'!$C$7:$C$463,$B3,'06-2026'!$A$7:$A$463,"Termination",'06-2026'!$I$7:$I$463,$C3,'06-2026'!$CE$7:$CE$463,$A3) -> 1 | J3: =SUM(D3,F3,H3) -> 16202924 | K3: =SUM(E3,G3,I3) -> 1
A4: =A3 -> MEKONG SUBLABOR | B4: PL | C4: VN1033 | D4: =SUMIFS('06-2026'!$CB$7:$CB$463,'06-2026'!$C$7:$C$463,$B4,'06-2026'!$A$7:$A$463,"Out",'06-2026'!$I$7:$I$463,$C4,'06-2026'!$CE$7:$CE$463,$A4) -> 17498466 | E4: =COUNTIFS('06-2026'!$C$7:$C$463,$B4,'06-2026'!$A$7:$A$463,"Out",'06-2026'!$I$7:$I$463,$C4,'06-2026'!$CE$7:$CE$463,$A4) -> 1 | F4: =SUMIFS('06-2026'!$CB$7:$CB$463,'06-2026'!$C$7:$C$463,$B4,'06-2026'!$A$7:$A$463,"Out-New",'06-2026'!$I$7:$I$463,$C4,'06-2026'!$CE$7:$CE$463,$A4) -> 0 | G4: =COUNTIFS('06-2026'!$C$7:$C$463,$B4,'06-2026'!$A$7:$A$463,"Out-New",'06-2026'!$I$7:$I$463,$C4,'06-2026'!$CE$7:$CE$463,$A4) -> 0 | H4: =SUMIFS('06-2026'!$CB$7:$CB$463,'06-2026'!$C$7:$C$463,$B4,'06-2026'!$A$7:$A$463,"Termination",'06-2026'!$I$7:$I$463,$C4,'06-2026'!$CE$7:$CE$463,$A4) -> 0 | I4: =COUNTIFS('06-2026'!$C$7:$C$463,$B4,'06-2026'!$A$7:$A$463,"Termination",'06-2026'!$I$7:$I$463,$C4,'06-2026'!$CE$7:$CE$463,$A4) -> 0 | J4: =SUM(D4,F4,H4) -> 17498466 | K4: =SUM(E4,G4,I4) -> 1
A5: =A4 -> MEKONG SUBLABOR | B5: LG | C5: VN1042 | D5: =SUMIFS('06-2026'!$CB$7:$CB$463,'06-2026'!$C$7:$C$463,$B5,'06-2026'!$A$7:$A$463,"Out",'06-2026'!$I$7:$I$463,$C5,'06-2026'!$CE$7:$CE$463,$A5) -> 73950375 | E5: =COUNTIFS('06-2026'!$C$7:$C$463,$B5,'06-2026'!$A$7:$A$463,"Out",'06-2026'!$I$7:$I$463,$C5,'06-2026'!$CE$7:$CE$463,$A5) -> 6 | F5: =SUMIFS('06-2026'!$CB$7:$CB$463,'06-2026'!$C$7:$C$463,$B5,'06-2026'!$A$7:$A$463,"Out-New",'06-2026'!$I$7:$I$463,$C5,'06-2026'!$CE$7:$CE$463,$A5) -> 0 | G5: =COUNTIFS('06-2026'!$C$7:$C$463,$B5,'06-2026'!$A$7:$A$463,"Out-New",'06-2026'!$I$7:$I$463,$C5,'06-2026'!$CE$7:$CE$463,$A5) -> 0 | H5: =SUMIFS('06-2026'!$CB$7:$CB$463,'06-2026'!$C$7:$C$463,$B5,'06-2026'!$A$7:$A$463,"Termination",'06-2026'!$I$7:$I$463,$C5,'06-2026'!$CE$7:$CE$463,$A5) -> 3896830 | I5: =COUNTIFS('06-2026'!$C$7:$C$463,$B5,'06-2026'!$A$7:$A$463,"Termination",'06-2026'!$I$7:$I$463,$C5,'06-2026'!$CE$7:$CE$463,$A5) -> 2 | J5: =SUM(D5,F5,H5) -> 77847205 | K5: =SUM(E5,G5,I5) -> 8
A6: =A5 -> MEKONG SUBLABOR | B6: LG Total | D6: =SUM(D3:D5) -> 91448841 | E6: =SUM(E3:E5) -> 7 | F6: =SUM(F3:F5) -> 0 | G6: =SUM(G3:G5) -> 0 | H6: =SUM(H3:H5) -> 20099754 | I6: =SUM(I3:I5) -> 3 | J6: =SUM(J3:J5) -> 111548595 | K6: =SUM(K3:K5) -> 10
A7: =A6 -> MEKONG SUBLABOR | B7: ME | C7: VN1002 | D7: =SUMIFS('06-2026'!$CB$7:$CB$463,'06-2026'!$C$7:$C$463,$B7,'06-2026'!$A$7:$A$463,"Out",'06-2026'!$I$7:$I$463,$C7,'06-2026'!$CE$7:$CE$463,$A7) -> 0 | E7: =COUNTIFS('06-2026'!$C$7:$C$463,$B7,'06-2026'!$A$7:$A$463,"Out",'06-2026'!$I$7:$I$463,$C7,'06-2026'!$CE$7:$CE$463,$A7) -> 0 | F7: =SUMIFS('06-2026'!$CB$7:$CB$463,'06-2026'!$C$7:$C$463,$B7,'06-2026'!$A$7:$A$463,"Out-New",'06-2026'!$I$7:$I$463,$C7,'06-2026'!$CE$7:$CE$463,$A7) -> 0 | G7: =COUNTIFS('06-2026'!$C$7:$C$463,$B7,'06-2026'!$A$7:$A$463,"Out-New",'06-2026'!$I$7:$I$463,$C7,'06-2026'!$CE$7:$CE$463,$A7) -> 0 | H7: =SUMIFS('06-2026'!$CB$7:$CB$463,'06-2026'!$C$7:$C$463,$B7,'06-2026'!$A$7:$A$463,"Termination",'06-2026'!$I$7:$I$463,$C7,'06-2026'!$CE$7:$CE$463,$A7) -> 0 | I7: =COUNTIFS('06-2026'!$C$7:$C$463,$B7,'06-2026'!$A$7:$A$463,"Termination",'06-2026'!$I$7:$I$463,$C7,'06-2026'!$CE$7:$CE$463,$A7) -> 0 | J7: =SUM(D7,F7,H7) -> 0 | K7: =SUM(E7,G7,I7) -> 0
A8: =A7 -> MEKONG SUBLABOR | B8: =B7 -> ME | C8: VN1006 | D8: =SUMIFS('06-2026'!$CB$7:$CB$463,'06-2026'!$C$7:$C$463,$B8,'06-2026'!$A$7:$A$463,"Out",'06-2026'!$I$7:$I$463,$C8,'06-2026'!$CE$7:$CE$463,$A8) -> 0 | E8: =COUNTIFS('06-2026'!$C$7:$C$463,$B8,'06-2026'!$A$7:$A$463,"Out",'06-2026'!$I$7:$I$463,$C8,'06-2026'!$CE$7:$CE$463,$A8) -> 0 | F8: =SUMIFS('06-2026'!$CB$7:$CB$463,'06-2026'!$C$7:$C$463,$B8,'06-2026'!$A$7:$A$463,"Out-New",'06-2026'!$I$7:$I$463,$C8,'06-2026'!$CE$7:$CE$463,$A8) -> 0 | G8: =COUNTIFS('06-2026'!$C$7:$C$463,$B8,'06-2026'!$A$7:$A$463,"Out-New",'06-2026'!$I$7:$I$463,$C8,'06-2026'!$CE$7:$CE$463,$A8) -> 0 | H8: =SUMIFS('06-2026'!$CB$7:$CB$463,'06-2026'!$C$7:$C$463,$B8,'06-2026'!$A$7:$A$463,"Termination",'06-2026'!$I$7:$I$463,$C8,'06-2026'!$CE$7:$CE$463,$A8) -> 0 | I8: =COUNTIFS('06-2026'!$C$7:$C$463,$B8,'06-2026'!$A$7:$A$463,"Termination",'06-2026'!$I$7:$I$463,$C8,'06-2026'!$CE$7:$CE$463,$A8) -> 0 | J8: =SUM(D8,F8,H8) -> 0 | K8: =SUM(E8,G8,I8) -> 0
A9: =A8 -> MEKONG SUBLABOR | B9: =B8 -> ME | C9: VN1021 | D9: =SUMIFS('06-2026'!$CB$7:$CB$463,'06-2026'!$C$7:$C$463,$B9,'06-2026'!$A$7:$A$463,"Out",'06-2026'!$I$7:$I$463,$C9,'06-2026'!$CE$7:$CE$463,$A9) -> 0 | E9: =COUNTIFS('06-2026'!$C$7:$C$463,$B9,'06-2026'!$A$7:$A$463,"Out",'06-2026'!$I$7:$I$463,$C9,'06-2026'!$CE$7:$CE$463,$A9) -> 0 | F9: =SUMIFS('06-2026'!$CB$7:$CB$463,'06-2026'!$C$7:$C$463,$B9,'06-2026'!$A$7:$A$463,"Out-New",'06-2026'!$I$7:$I$463,$C9,'06-2026'!$CE$7:$CE$463,$A9) -> 0 | G9: =COUNTIFS('06-2026'!$C$7:$C$463,$B9,'06-2026'!$A$7:$A$463,"Out-New",'06-2026'!$I$7:$I$463,$C9,'06-2026'!$CE$7:$CE$463,$A9) -> 0 | H9: =SUMIFS('06-2026'!$CB$7:$CB$463,'06-2026'!$C$7:$C$463,$B9,'06-2026'!$A$7:$A$463,"Termination",'06-2026'!$I$7:$I$463,$C9,'06-2026'!$CE$7:$CE$463,$A9) -> 0 | I9: =COUNTIFS('06-2026'!$C$7:$C$463,$B9,'06-2026'!$A$7:$A$463,"Termination",'06-2026'!$I$7:$I$463,$C9,'06-2026'!$CE$7:$CE$463,$A9) -> 0 | J9: =SUM(D9,F9,H9) -> 0 | K9: =SUM(E9,G9,I9) -> 0
A10: =A9 -> MEKONG SUBLABOR | B10: ME Total | D10: =SUM(D7:D9) -> 0 | E10: =SUM(E7:E9) -> 0 | F10: =SUM(F7:F9) -> 0 | G10: =SUM(G7:G9) -> 0 | H10: =SUM(H7:H9) -> 0 | I10: =SUM(I7:I9) -> 0 | J10: =SUM(J7:J9) -> 0 | K10: =SUM(K7:K9) -> 0
A11: =A10 -> MEKONG SUBLABOR | B11: MM | C11: VN1054 | D11: =SUMIFS('06-2026'!$CB$7:$CB$463,'06-2026'!$C$7:$C$463,$B11,'06-2026'!$A$7:$A$463,"Out",'06-2026'!$I$7:$I$463,$C11,'06-2026'!$CE$7:$CE$463,$A11) -> 13858560 | E11: =COUNTIFS('06-2026'!$C$7:$C$463,$B11,'06-2026'!$A$7:$A$463,"Out",'06-2026'!$I$7:$I$463,$C11,'06-2026'!$CE$7:$CE$463,$A11) -> 1 | F11: =SUMIFS('06-2026'!$CB$7:$CB$463,'06-2026'!$C$7:$C$463,$B11,'06-2026'!$A$7:$A$463,"Out-New",'06-2026'!$I$7:$I$463,$C11,'06-2026'!$CE$7:$CE$463,$A11) -> 0 | G11: =COUNTIFS('06-2026'!$C$7:$C$463,$B11,'06-2026'!$A$7:$A$463,"Out-New",'06-2026'!$I$7:$I$463,$C11,'06-2026'!$CE$7:$CE$463,$A11) -> 0 | H11: =SUMIFS('06-2026'!$CB$7:$CB$463,'06-2026'!$C$7:$C$463,$B11,'06-2026'!$A$7:$A$463,"Termination",'06-2026'!$I$7:$I$463,$C11,'06-2026'!$CE$7:$CE$463,$A11) -> 0 | I11: =COUNTIFS('06-2026'!$C$7:$C$463,$B11,'06-2026'!$A$7:$A$463,"Termination",'06-2026'!$I$7:$I$463,$C11,'06-2026'!$CE$7:$CE$463,$A11) -> 0 | J11: =SUM(D11,F11,H11) -> 13858560 | K11: =SUM(E11,G11,I11) -> 1
A12: =A11 -> MEKONG SUBLABOR | B12: MM Total | D12: =D11 -> 13858560 | E12: =E11 -> 1 | F12: =F11 -> 0 | G12: =G11 -> 0 | H12: =H11 -> 0 | I12: =I11 -> 0 | J12: =J11 -> 13858560 | K12: =K11 -> 1
A13: =A12 -> MEKONG SUBLABOR | B13: FIN | C13: VN7040 | D13: =SUMIFS('06-2026'!$CB$7:$CB$463,'06-2026'!$C$7:$C$463,$B13,'06-2026'!$A$7:$A$463,"Out",'06-2026'!$I$7:$I$463,$C13,'06-2026'!$CE$7:$CE$463,$A13) -> 0 | E13: =COUNTIFS('06-2026'!$C$7:$C$463,$B13,'06-2026'!$A$7:$A$463,"Out",'06-2026'!$I$7:$I$463,$C13,'06-2026'!$CE$7:$CE$463,$A13) -> 0 | F13: =SUMIFS('06-2026'!$CB$7:$CB$463,'06-2026'!$C$7:$C$463,$B13,'06-2026'!$A$7:$A$463,"Out-New",'06-2026'!$I$7:$I$463,$C13,'06-2026'!$CE$7:$CE$463,$A13) -> 0 | G13: =COUNTIFS('06-2026'!$C$7:$C$463,$B13,'06-2026'!$A$7:$A$463,"Out-New",'06-2026'!$I$7:$I$463,$C13,'06-2026'!$CE$7:$CE$463,$A13) -> 0 | H13: =SUMIFS('06-2026'!$CB$7:$CB$463,'06-2026'!$C$7:$C$463,$B13,'06-2026'!$A$7:$A$463,"Termination",'06-2026'!$I$7:$I$463,$C13,'06-2026'!$CE$7:$CE$463,$A13) -> 0 | I13: =COUNTIFS('06-2026'!$C$7:$C$463,$B13,'06-2026'!$A$7:$A$463,"Termination",'06-2026'!$I$7:$I$463,$C13,'06-2026'!$CE$7:$CE$463,$A13) -> 0 | J13: =SUM(D13,F13,H13) -> 0 | K13: =SUM(E13,G13,I13) -> 0
A14: =A13 -> MEKONG SUBLABOR | B14: FIN | C14: VN7043 | D14: =SUMIFS('06-2026'!$CB$7:$CB$463,'06-2026'!$C$7:$C$463,$B14,'06-2026'!$A$7:$A$463,"Out",'06-2026'!$I$7:$I$463,$C14,'06-2026'!$CE$7:$CE$463,$A14) -> 0 | E14: =COUNTIFS('06-2026'!$C$7:$C$463,$B14,'06-2026'!$A$7:$A$463,"Out",'06-2026'!$I$7:$I$463,$C14,'06-2026'!$CE$7:$CE$463,$A14) -> 0 | F14: =SUMIFS('06-2026'!$CB$7:$CB$463,'06-2026'!$C$7:$C$463,$B14,'06-2026'!$A$7:$A$463,"Out-New",'06-2026'!$I$7:$I$463,$C14,'06-2026'!$CE$7:$CE$463,$A14) -> 0 | G14: =COUNTIFS('06-2026'!$C$7:$C$463,$B14,'06-2026'!$A$7:$A$463,"Out-New",'06-2026'!$I$7:$I$463,$C14,'06-2026'!$CE$7:$CE$463,$A14) -> 0 | H14: =SUMIFS('06-2026'!$CB$7:$CB$463,'06-2026'!$C$7:$C$463,$B14,'06-2026'!$A$7:$A$463,"Termination",'06-2026'!$I$7:$I$463,$C14,'06-2026'!$CE$7:$CE$463,$A14) -> 0 | I14: =COUNTIFS('06-2026'!$C$7:$C$463,$B14,'06-2026'!$A$7:$A$463,"Termination",'06-2026'!$I$7:$I$463,$C14,'06-2026'!$CE$7:$CE$463,$A14) -> 0 | J14: =SUM(D14,F14,H14) -> 0 | K14: =SUM(E14,G14,I14) -> 0
A15: =A13 -> MEKONG SUBLABOR | B15: FIN Total | D15: =SUM(D13:D14) -> 0 | E15: =SUM(E13:E14) -> 0 | F15: =SUM(F13:F14) -> 0 | G15: =SUM(G13:G14) -> 0 | H15: =SUM(H13:H14) -> 0 | I15: =SUM(I13:I14) -> 0 | J15: =SUM(J13:J14) -> 0 | K15: =SUM(K13:K14) -> 0
A16: =A15 -> MEKONG SUBLABOR | B16: PD | C16: VN1001 | D16: =SUMIFS('06-2026'!$CB$7:$CB$463,'06-2026'!$C$7:$C$463,$B16,'06-2026'!$A$7:$A$463,"Out",'06-2026'!$I$7:$I$463,$C16,'06-2026'!$CE$7:$CE$463,$A16) -> 5.5380531e+08 | E16: =COUNTIFS('06-2026'!$C$7:$C$463,$B16,'06-2026'!$A$7:$A$463,"Out",'06-2026'!$I$7:$I$463,$C16,'06-2026'!$CE$7:$CE$463,$A16) -> 35 | F16: =SUMIFS('06-2026'!$CB$7:$CB$463,'06-2026'!$C$7:$C$463,$B16,'06-2026'!$A$7:$A$463,"Out-New",'06-2026'!$I$7:$I$463,$C16,'06-2026'!$CE$7:$CE$463,$A16) -> 0 | G16: =COUNTIFS('06-2026'!$C$7:$C$463,$B16,'06-2026'!$A$7:$A$463,"Out-New",'06-2026'!$I$7:$I$463,$C16,'06-2026'!$CE$7:$CE$463,$A16) -> 0 | H16: =SUMIFS('06-2026'!$CB$7:$CB$463,'06-2026'!$C$7:$C$463,$B16,'06-2026'!$A$7:$A$463,"Termination",'06-2026'!$I$7:$I$463,$C16,'06-2026'!$CE$7:$CE$463,$A16) -> 37394117 | I16: =COUNTIFS('06-2026'!$C$7:$C$463,$B16,'06-2026'!$A$7:$A$463,"Termination",'06-2026'!$I$7:$I$463,$C16,'06-2026'!$CE$7:$CE$463,$A16) -> 4 | J16: =SUM(D16,F16,H16) -> 5.9119943e+08 | K16: =SUM(E16,G16,I16) -> 39
